Workbook
Name Spóźnione: #REF!

Sheet Zestawienie
A1: ZESTAWIENIE PRZYDZIAŁÓW TERENÓW — Rok służbowy 2025/2026
A2: Teren nr | B2: Data ostatniego opracowania | C2: Przydzielono | E2: Przydzielono | G2: Przydzielono | I2: Przydzielono | K2: Przydzielono
C3: Data przydziału | D3: Data opracowania | E3: Data przydziału | F3: Data opracowania | G3: Data przydziału | H3: Data opracowania | I3: Data przydziału | J3: Data opracowania | K3: Data przydziału | L3: Data opracowania
A4: 1 | B4: =IFERROR(__xludf.DUMMYFUNCTION("IF(ISBLANK(D5),"""",MAX(FILTER({D5;F5;H5;J5;L5}, ISNUMBER({D5;F5;H5;J5;L5}))))"),46186.0) -> 46186 | C4: Stolarz Daniel | E4: Winnicki Krzysztof | G4: Winnicki Krzysztof
C5: 45710 | D5: 45772 | E5: 45986 | F5: 45991 | G5: 46162 | H5: 46186
A6: 2 | B6: =IFERROR(__xludf.DUMMYFUNCTION("IF(ISBLANK(D7),"""",MAX(FILTER({D7;F7;H7;J7;L7}, ISNUMBER({D7;F7;H7;J7;L7}))))"),46130.0) -> 46130 | C6: Olender Aleksandra | E6: Winnicki Krzysztof
C7: 45851 | D7: 45963 | E7: 46091 | F7: 46130
A8: 3 | B8: =IFERROR(__xludf.DUMMYFUNCTION("IF(ISBLANK(D9),"""",MAX(FILTER({D9;F9;H9;J9;L9}, ISNUMBER({D9;F9;H9;J9;L9}))))"),46082.0) -> 46082 | C8: Stolarz Daniel | E8: Olender Aleksandra
C9: 45745 | D9: 45752 | E9: 45995 | F9: 46082
A10: 4 | B10: =IFERROR(__xludf.DUMMYFUNCTION("IF(ISBLANK(D11),"""",MAX(FILTER({D11;F11;H11;J11;L11}, ISNUMBER({D11;F11;H11;J11;L11}))))"),46221.0) -> 46221 | C10: Wojewódzki Kamil | E10: Kwiatkowska Kinga
C11: 45897 | D11: 45978 | E11: 46108 | F11: 46221
A12: 5 | B12: =IFERROR(__xludf.DUMMYFUNCTION("IF(ISBLANK(D13),"""",MAX(FILTER({D13;F13;H13;J13;L13}, ISNUMBER({D13;F13;H13;J13;L13}))))"),46081.0) -> 46081 | C12: Milewska Anna | E12: Winnicki Krzysztof
C13: 45888 | D13: 45929 | E13: 46037 | F13: 46081
A14: 6 | B14: =IFERROR(__xludf.DUMMYFUNCTION("IF(ISBLANK(D15),"""",MAX(FILTER({D15;F15;H15;J15;L15}, ISNUMBER({D15;F15;H15;J15;L15}))))"),45991.0) -> 45991 | C14: Pieśniewski Kazimierz | E14: Winnicki Krzysztof
C15: 40933 | D15: 45755 | E15: 45981 | F15: 45991
A16: 7 | B16: =IFERROR(__xludf.DUMMYFUNCTION("IF(ISBLANK(D17),"""",MAX(FILTER({D17;F17;H17;J17;L17}, ISNUMBER({D17;F17;H17;J17;L17}))))"),46121.0) -> 46121 | C16: Geszczyński Tomasz | E16: Winnicki Krzysztof
C17: 45888 | D17: 45930 | E17: 46106 | F17: 46121
A18: 8 | B18: =IFERROR(__xludf.DUMMYFUNCTION("IF(ISBLANK(D19),"""",MAX(FILTER({D19;F19;H19;J19;L19}, ISNUMBER({D19;F19;H19;J19;L19}))))"),46024.0) -> 46024 | C18: Milewska Anna | E18: Winnicki Krzysztof
C19: 45669 | D19: 45755 | E19: 46011 | F19: 46024
A20: 9 | B20: =IFERROR(__xludf.DUMMYFUNCTION("IF(ISBLANK(D21),"""",MAX(FILTER({D21;F21;H21;J21;L21}, ISNUMBER({D21;F21;H21;J21;L21}))))"),46184.0) -> 46184 | C20: Wojewódzki Kamil | E20: Piechota Ireneusz
C21: 45771 | D21: 45929 | E21: 46143 | F21: 46184
A22: 10 | B22: =IFERROR(__xludf.DUMMYFUNCTION("IF(ISBLANK(D23),"""",MAX(FILTER({D23;F23;H23;J23;L23}, ISNUMBER({D23;F23;H23;J23;L23}))))"),46186.0) -> 46186 | C22: Piechota Ireneusz | E22: Wojewódzki Kamil
C23: 45888 | D23: 45935 | E23: 46122 | F23: 46186
A24: 11 | B24: =IFERROR(__xludf.DUMMYFUNCTION("IF(ISBLANK(D25),"""",MAX(FILTER({D25;F25;H25;J25;L25}, ISNUMBER({D25;F25;H25;J25;L25}))))"),46187.0) -> 46187 | C24: Krzyżanowski Władysław | E24: Stachyra Witold
C25: 45830 | D25: 45900 | E25: 46107 | F25: 46187
A26: 12 | B26: =IFERROR(__xludf.DUMMYFUNCTION("IF(ISBLANK(D27),"""",MAX(FILTER({D27;F27;H27;J27;L27}, ISNUMBER({D27;F27;H27;J27;L27}))))"),45991.0) -> 45991 | C26: Piechota Ireneusz | E26: Migrała Wioletta
C27: 45888 | D27: 45991 | E27: 46133
A28: 13 | B28: =IFERROR(__xludf.DUMMYFUNCTION("IF(ISBLANK(D29),"""",MAX(FILTER({D29;F29;H29;J29;L29}, ISNUMBER({D29;F29;H29;J29;L29}))))"),46175.0) -> 46175 | C28: Słupski Michał | E28: Milewska Anna
C29: 45815 | D29: 45888 | E29: 46107 | F29: 46175
A30: 14 | B30: =IFERROR(__xludf.DUMMYFUNCTION("IF(ISBLANK(D31),"""",MAX(FILTER({D31;F31;H31;J31;L31}, ISNUMBER({D31;F31;H31;J31;L31}))))"),46186.0) -> 46186 | C30: Milewska Anna | E30: Wojewódzki Kamil
C31: 45853 | D31: 45937 | E31: 46117 | F31: 46186
A32: 15 | B32: =IFERROR(__xludf.DUMMYFUNCTION("IF(ISBLANK(D33),"""",MAX(FILTER({D33;F33;H33;J33;L33}, ISNUMBER({D33;F33;H33;J33;L33}))))"),46071.0) -> 46071 | C32: Piechota Ireneusz | E32: Winnicki Krzysztof
C33: 45708 | D33: 45732 | E33: 46042 | F33: 46071
A34: 16 | B34: =IFERROR(__xludf.DUMMYFUNCTION("IF(ISBLANK(D35),"""",MAX(FILTER({D35;F35;H35;J35;L35}, ISNUMBER({D35;F35;H35;J35;L35}))))"),46149.0) -> 46149 | C34: Winnicki Krzysztof | E34: Geszczyński Tomasz
C35: 45776 | D35: 45837 | E35: 46109 | F35: 46149
A36: 17 | B36: =IFERROR(__xludf.DUMMYFUNCTION("IF(ISBLANK(D37),"""",MAX(FILTER({D37;F37;H37;J37;L37}, ISNUMBER({D37;F37;H37;J37;L37}))))"),46131.0) -> 46131 | C36: Geszczyński Tomasz | E36: Milewska Anna
C37: 45773 | D37: 45865 | E37: 46071 | F37: 46131
A38: 18 | B38: =IFERROR(__xludf.DUMMYFUNCTION("IF(ISBLANK(D39),"""",MAX(FILTER({D39;F39;H39;J39;L39}, ISNUMBER({D39;F39;H39;J39;L39}))))"),"") | C38: Grabowska Lidia
C39: 45776
A40: 19 | B40: =IFERROR(__xludf.DUMMYFUNCTION("IF(ISBLANK(D41),"""",MAX(FILTER({D41;F41;H41;J41;L41}, ISNUMBER({D41;F41;H41;J41;L41}))))"),45914.0) -> 45914 | C40: Słupski Michał | E40: Wojewódzki Kamil
...

Sheet Skrócone zestawienie
A1: Teren nr | B1: Głosiciel | C1: Wolny / Zajęty | D1: Od ilu dni | E1: Ile terenów przydzielonych ma głosiciel
A2: 1 | B2: =IFERROR(__xludf.DUMMYFUNCTION("IF( OR(C2=""Zajęte"", C2=""Spóźnione""), IFERROR( INDEX( FILTER( { INDEX(Zestawienie!K:K, ROW()*2); INDEX(Zestawienie!I:I, ROW()*2); INDEX(Zestawienie!G:G, ROW()*2); INDEX(Zestawienie!E:E, ROW("&")*2); INDEX(Zestawienie!C:C, ROW()*2) }, { INDEX(Zestawienie!K:K, ROW()*2)<>"""" ; INDEX(Zestawienie!I:I, ROW()*2)<>"""" ; INDEX(Zestawienie!G:G, ROW()*2)<>"""" ; INDEX(Zestawienie!E:E, ROW"&"()*2)<>"""" ; INDEX(Zestawienie!C:C, ROW()*2)<>"""" } ), 1 ), """" ), """" ) "),"") | C2: {=IF( OR( AND(NOT(ISBLANK(INDEX(Zestawienie!C:C,ROW()*2+1))), INDEX(Zestawienie!C:C,ROW()*2+1)<TODAY()-120, ISBLANK(INDEX(Zestawienie!D:D,ROW()*2+1))), AND(NOT(ISBLANK(INDEX(Zestawienie!E:E,ROW()*2+1))), INDEX(Zestawienie!E:E,ROW()*2+1)<TODAY()-120, ISBLANK(INDEX(Zestawienie!F:F,ROW()*2+1))), AND(NOT(ISBLANK(INDEX(Zestawienie!G:G,ROW()*2+1))), INDEX(Zestawienie!G:G,ROW()*2+1)<TODAY()-120, ISBLANK(INDEX(Zestawienie!H:H,ROW()*2+1))), AND(NOT(ISBLANK(INDEX(Zestawienie!I:I,ROW()*2+1))), INDEX(Zestawienie!I:I,ROW()*2+1)<TODAY()-120, ISBLANK(INDEX(Zestawienie!J:J,ROW()*2+1))), AND(NOT(ISBLANK(INDEX(Zestawienie!K:K,ROW()*2+1))), INDEX(Zestawienie!K:K,ROW()*2+1)<TODAY()-120, ISBLANK(INDEX(Zestawienie!L:L,ROW()*2+1))) ), "Spóźnione", IF( OR( AND(NOT(ISBLANK(INDEX(Zestawienie!C:C,ROW()*2+1))), ISBLANK(INDEX(Zestawienie!D:D,ROW()*2+1))), AND(NOT(ISBLANK(INDEX(Zestawienie!E:E,ROW()*2+1))), ISBLANK(INDEX(Zestawienie!F:F,ROW()*2+1))), AND(NOT(ISBLANK(INDEX(Zestawienie!G:G,ROW()*2+1))), ISBLANK(INDEX(Zestawienie!H:H,ROW()*2+1))), AND(NOT(ISBLANK(INDEX(Zestawienie!I:I,ROW()*2+1))), ISBLANK(INDEX(Zestawienie!J:J,ROW()*2+1))), AND(NOT(ISBLANK(INDEX(Zestawienie!K:K,ROW()*2+1))), ISBLANK(INDEX(Zestawienie!L:L,ROW()*2+1))) ), "Zajęte", "Wolne" ) )} -> Wolne | D2: {=IFERROR( IF( ISBLANK(INDEX(Zestawienie!B:B, MATCH(A2, Zestawienie!A:A, 0))), "", IF(C2="Wolne", IF( OR( ISBLANK(INDEX(Zestawienie!B:B, MATCH(A2, Zestawienie!A:A, 0))), NOT(ISNUMBER(INDEX(Zestawienie!B:B, MATCH(A2, Zestawienie!A:A, 0)))) ), "", TODAY()-INDEX(Zestawienie!B:B, MATCH(A2, Zestawienie!A:A, 0)) ), IF(OR(C2="Zajęte", C2="Spóźnione"), IF( ISBLANK( MAX( IF(ISNUMBER(INDEX(Zestawienie!C:C, 2*ROW()+1)), INDEX(Zestawienie!C:C, 2*ROW()+1), 0), IF(ISNUMBER(INDEX(Zestawienie!E:E, 2*ROW()+1)), INDEX(Zestawienie!E:E, 2*ROW()+1), 0), IF(ISNUMBER(INDEX(Zestawienie!G:G, 2*ROW()+1)), INDEX(Zestawienie!G:G, 2*ROW()+1), 0), IF(ISNUMBER(INDEX(Zestawienie!I:I, 2*ROW()+1)), INDEX(Zestawienie!I:I, 2*ROW()+1), 0), IF(ISNUMBER(INDEX(Zestawienie!K:K, 2*ROW()+1)), INDEX(Zestawienie!K:K, 2*ROW()+1), 0) ) ), "", IF(C2="Zajęte", TODAY()-MAX( IF(ISNUMBER(INDEX(Zestawienie!C:C, 2*ROW()+1)), INDEX(Zestawienie!C:C, 2*ROW()+1), 0), IF(ISNUMBER(INDEX(Zestawienie!E:E, 2*ROW()+1)), INDEX(Zestawienie!E:E, 2*ROW()+1), 0), IF(ISNUMBER(INDEX(Zestawienie!G:G, 2*ROW()+1)), INDEX(Zestawienie!G:G, 2*ROW()+1), 0), IF(ISNUMBER(INDEX(Zestawienie!I:I, 2*ROW()+1)), INDEX(Zestawienie!I:I, 2*ROW()+1), 0), IF(ISNUMBER(INDEX(Zestawienie!K:K, 2*ROW()+1)), INDEX(Zestawienie!K:K, 2*ROW()+1), 0) ), MAX(0, TODAY()-MAX( IF(ISNUMBER(INDEX(Zestawienie!C:C, 2*ROW()+1)), INDEX(Zestawienie!C:C, 2*ROW()+1), 0), IF(ISNUMBER(INDEX(Zestawienie!E:E, 2*ROW()+1)), INDEX(Zestawienie!E:E, 2*ROW()+1), 0), IF(ISNUMBER(INDEX(Zestawienie!G:G, 2*ROW()+1)), INDEX(Zestawienie!G:G, 2*ROW()+1), 0), IF(ISNUMBER(INDEX(Zestawienie!I:I, 2*ROW()+1)), INDEX(Zestawienie!I:I, 2*ROW()+1), 0), IF(ISNUMBER(INDEX(Zestawienie!K:K, 2*ROW()+1)), INDEX(Zestawienie!K:K, 2*ROW()+1), 0) )-120) ) ), "" ) ) ), "")} -> 93
A3: 2 | B3: =IFERROR(__xludf.DUMMYFUNCTION("IF( OR(C3=""Zajęte"", C3=""Spóźnione""), IFERROR( INDEX( FILTER( { INDEX(Zestawienie!K:K, ROW()*2); INDEX(Zestawienie!I:I, ROW()*2); INDEX(Zestawienie!G:G, ROW()*2); INDEX(Zestawienie!E:E, ROW("&")*2); INDEX(Zestawienie!C:C, ROW()*2) }, { INDEX(Zestawienie!K:K, ROW()*2)<>"""" ; INDEX(Zestawienie!I:I, ROW()*2)<>"""" ; INDEX(Zestawienie!G:G, ROW()*2)<>"""" ; INDEX(Zestawienie!E:E, ROW"&"()*2)<>"""" ; INDEX(Zestawienie!C:C, ROW()*2)<>"""" } ), 1 ), """" ), """" ) "),"") | C3: {=IF( OR( AND(NOT(ISBLANK(INDEX(Zestawienie!C:C,ROW()*2+1))), INDEX(Zestawienie!C:C,ROW()*2+1)<TODAY()-120, ISBLANK(INDEX(Zestawienie!D:D,ROW()*2+1))), AND(NOT(ISBLANK(INDEX(Zestawienie!E:E,ROW()*2+1))), INDEX(Zestawienie!E:E,ROW()*2+1)<TODAY()-120, ISBLANK(INDEX(Zestawienie!F:F,ROW()*2+1))), AND(NOT(ISBLANK(INDEX(Zestawienie!G:G,ROW()*2+1))), INDEX(Zestawienie!G:G,ROW()*2+1)<TODAY()-120, ISBLANK(INDEX(Zestawienie!H:H,ROW()*2+1))), AND(NOT(ISBLANK(INDEX(Zestawienie!I:I,ROW()*2+1))), INDEX(Zestawienie!I:I,ROW()*2+1)<TODAY()-120, ISBLANK(INDEX(Zestawienie!J:J,ROW()*2+1))), AND(NOT(ISBLANK(INDEX(Zestawienie!K:K,ROW()*2+1))), INDEX(Zestawienie!K:K,ROW()*2+1)<TODAY()-120, ISBLANK(INDEX(Zestawienie!L:L,ROW()*2+1))) ), "Spóźnione", IF( OR( AND(NOT(ISBLANK(INDEX(Zestawienie!C:C,ROW()*2+1))), ISBLANK(INDEX(Zestawienie!D:D,ROW()*2+1))), AND(NOT(ISBLANK(INDEX(Zestawienie!E:E,ROW()*2+1))), ISBLANK(INDEX(Zestawienie!F:F,ROW()*2+1))), AND(NOT(ISBLANK(INDEX(Zestawienie!G:G,ROW()*2+1))), ISBLANK(INDEX(Zestawienie!H:H,ROW()*2+1))), AND(NOT(ISBLANK(INDEX(Zestawienie!I:I,ROW()*2+1))), ISBLANK(INDEX(Zestawienie!J:J,ROW()*2+1))), AND(NOT(ISBLANK(INDEX(Zestawienie!K:K,ROW()*2+1))), ISBLANK(INDEX(Zestawienie!L:L,ROW()*2+1))) ), "Zajęte", "Wolne" ) )} -> Wolne | D3: {=IFERROR( IF( ISBLANK(INDEX(Zestawienie!B:B, MATCH(A3, Zestawienie!A:A, 0))), "", IF(C3="Wolne", IF( OR( ISBLANK(INDEX(Zestawienie!B:B, MATCH(A3, Zestawienie!A:A, 0))), NOT(ISNUMBER(INDEX(Zestawienie!B:B, MATCH(A3, Zestawienie!A:A, 0)))) ), "", TODAY()-INDEX(Zestawienie!B:B, MATCH(A3, Zestawienie!A:A, 0)) ), IF(OR(C3="Zajęte", C3="Spóźnione"), IF( ISBLANK( MAX( IF(ISNUMBER(INDEX(Zestawienie!C:C, 2*ROW()+1)), INDEX(Zestawienie!C:C, 2*ROW()+1), 0), IF(ISNUMBER(INDEX(Zestawienie!E:E, 2*ROW()+1)), INDEX(Zestawienie!E:E, 2*ROW()+1), 0), IF(ISNUMBER(INDEX(Zestawienie!G:G, 2*ROW()+1)), INDEX(Zestawienie!G:G, 2*ROW()+1), 0), IF(ISNUMBER(INDEX(Zestawienie!I:I, 2*ROW()+1)), INDEX(Zestawienie!I:I, 2*ROW()+1), 0), IF(ISNUMBER(INDEX(Zestawienie!K:K, 2*ROW()+1)), INDEX(Zestawienie!K:K, 2*ROW()+1), 0) ) ), "", IF(C3="Zajęte", TODAY()-MAX( IF(ISNUMBER(INDEX(Zestawienie!C:C, 2*ROW()+1)), INDEX(Zestawienie!C:C, 2*ROW()+1), 0), IF(ISNUMBER(INDEX(Zestawienie!E:E, 2*ROW()+1)), INDEX(Zestawienie!E:E, 2*ROW()+1), 0), IF(ISNUMBER(INDEX(Zestawienie!G:G, 2*ROW()+1)), INDEX(Zestawienie!G:G, 2*ROW()+1), 0), IF(ISNUMBER(INDEX(Zestawienie!I:I, 2*ROW()+1)), INDEX(Zestawienie!I:I, 2*ROW()+1), 0), IF(ISNUMBER(INDEX(Zestawienie!K:K, 2*ROW()+1)), INDEX(Zestawienie!K:K, 2*ROW()+1), 0) ), MAX(0, TODAY()-MAX( IF(ISNUMBER(INDEX(Zestawienie!C:C, 2*ROW()+1)), INDEX(Zestawienie!C:C, 2*ROW()+1), 0), IF(ISNUMBER(INDEX(Zestawienie!E:E, 2*ROW()+1)), INDEX(Zestawienie!E:E, 2*ROW()+1), 0), IF(ISNUMBER(INDEX(Zestawienie!G:G, 2*ROW()+1)), INDEX(Zestawienie!G:G, 2*ROW()+1), 0), IF(ISNUMBER(INDEX(Zestawienie!I:I, 2*ROW()+1)), INDEX(Zestawienie!I:I, 2*ROW()+1), 0), IF(ISNUMBER(INDEX(Zestawienie!K:K, 2*ROW()+1)), INDEX(Zestawienie!K:K, 2*ROW()+1), 0) )-120) ) ), "" ) ) ), "")} -> 149
A4: 3 | B4: =IFERROR(__xludf.DUMMYFUNCTION("IF( OR(C4=""Zajęte"", C4=""Spóźnione""), IFERROR( INDEX( FILTER( { INDEX(Zestawienie!K:K, ROW()*2); INDEX(Zestawienie!I:I, ROW()*2); INDEX(Zestawienie!G:G, ROW()*2); INDEX(Zestawienie!E:E, ROW("&")*2); INDEX(Zestawienie!C:C, ROW()*2) }, { INDEX(Zestawienie!K:K, ROW()*2)<>"""" ; INDEX(Zestawienie!I:I, ROW()*2)<>"""" ; INDEX(Zestawienie!G:G, ROW()*2)<>"""" ; INDEX(Zestawienie!E:E, ROW"&"()*2)<>"""" ; INDEX(Zestawienie!C:C, ROW()*2)<>"""" } ), 1 ), """" ), """" ) "),"") | C4: {=IF( OR( AND(NOT(ISBLANK(INDEX(Zestawienie!C:C,ROW()*2+1))), INDEX(Zestawienie!C:C,ROW()*2+1)<TODAY()-120, ISBLANK(INDEX(Zestawienie!D:D,ROW()*2+1))), AND(NOT(ISBLANK(INDEX(Zestawienie!E:E,ROW()*2+1))), INDEX(Zestawienie!E:E,ROW()*2+1)<TODAY()-120, ISBLANK(INDEX(Zestawienie!F:F,ROW()*2+1))), AND(NOT(ISBLANK(INDEX(Zestawienie!G:G,ROW()*2+1))), INDEX(Zestawienie!G:G,ROW()*2+1)<TODAY()-120, ISBLANK(INDEX(Zestawienie!H:H,ROW()*2+1))), AND(NOT(ISBLANK(INDEX(Zestawienie!I:I,ROW()*2+1))), INDEX(Zestawienie!I:I,ROW()*2+1)<TODAY()-120, ISBLANK(INDEX(Zestawienie!J:J,ROW()*2+1))), AND(NOT(ISBLANK(INDEX(Zestawienie!K:K,ROW()*2+1))), INDEX(Zestawienie!K:K,ROW()*2+1)<TODAY()-120, ISBLANK(INDEX(Zestawienie!L:L,ROW()*2+1))) ), "Spóźnione", IF( OR( AND(NOT(ISBLANK(INDEX(Zestawienie!C:C,ROW()*2+1))), ISBLANK(INDEX(Zestawienie!D:D,ROW()*2+1))), AND(NOT(ISBLANK(INDEX(Zestawienie!E:E,ROW()*2+1))), ISBLANK(INDEX(Zestawienie!F:F,ROW()*2+1))), AND(NOT(ISBLANK(INDEX(Zestawienie!G:G,ROW()*2+1))), ISBLANK(INDEX(Zestawienie!H:H,ROW()*2+1))), AND(NOT(ISBLANK(INDEX(Zestawienie!I:I,ROW()*2+1))), ISBLANK(INDEX(Zestawienie!J:J,ROW()*2+1))), AND(NOT(ISBLANK(INDEX(Zestawienie!K:K,ROW()*2+1))), ISBLANK(INDEX(Zestawienie!L:L,ROW()*2+1))) ), "Zajęte", "Wolne" ) )} -> Wolne | D4: {=IFERROR( IF( ISBLANK(INDEX(Zestawienie!B:B, MATCH(A4, Zestawienie!A:A, 0))), "", IF(C4="Wolne", IF( OR( ISBLANK(INDEX(Zestawienie!B:B, MATCH(A4, Zestawienie!A:A, 0))), NOT(ISNUMBER(INDEX(Zestawienie!B:B, MATCH(A4, Zestawienie!A:A, 0)))) ), "", TODAY()-INDEX(Zestawienie!B:B, MATCH(A4, Zestawienie!A:A, 0)) ), IF(OR(C4="Zajęte", C4="Spóźnione"), IF( ISBLANK( MAX( IF(ISNUMBER(INDEX(Zestawienie!C:C, 2*ROW()+1)), INDEX(Zestawienie!C:C, 2*ROW()+1), 0), IF(ISNUMBER(INDEX(Zestawienie!E:E, 2*ROW()+1)), INDEX(Zestawienie!E:E, 2*ROW()+1), 0), IF(ISNUMBER(INDEX(Zestawienie!G:G, 2*ROW()+1)), INDEX(Zestawienie!G:G, 2*ROW()+1), 0), IF(ISNUMBER(INDEX(Zestawienie!I:I, 2*ROW()+1)), INDEX(Zestawienie!I:I, 2*ROW()+1), 0), IF(ISNUMBER(INDEX(Zestawienie!K:K, 2*ROW()+1)), INDEX(Zestawienie!K:K, 2*ROW()+1), 0) ) ), "", IF(C4="Zajęte", TODAY()-MAX( IF(ISNUMBER(INDEX(Zestawienie!C:C, 2*ROW()+1)), INDEX(Zestawienie!C:C, 2*ROW()+1), 0), IF(ISNUMBER(INDEX(Zestawienie!E:E, 2*ROW()+1)), INDEX(Zestawienie!E:E, 2*ROW()+1), 0), IF(ISNUMBER(INDEX(Zestawienie!G:G, 2*ROW()+1)), INDEX(Zestawienie!G:G, 2*ROW()+1), 0), IF(ISNUMBER(INDEX(Zestawienie!I:I, 2*ROW()+1)), INDEX(Zestawienie!I:I, 2*ROW()+1), 0), IF(ISNUMBER(INDEX(Zestawienie!K:K, 2*ROW()+1)), INDEX(Zestawienie!K:K, 2*ROW()+1), 0) ), MAX(0, TODAY()-MAX( IF(ISNUMBER(INDEX(Zestawienie!C:C, 2*ROW()+1)), INDEX(Zestawienie!C:C, 2*ROW()+1), 0), IF(ISNUMBER(INDEX(Zestawienie!E:E, 2*ROW()+1)), INDEX(Zestawienie!E:E, 2*ROW()+1), 0), IF(ISNUMBER(INDEX(Zestawienie!G:G, 2*ROW()+1)), INDEX(Zestawienie!G:G, 2*ROW()+1), 0), IF(ISNUMBER(INDEX(Zestawienie!I:I, 2*ROW()+1)), INDEX(Zestawienie!I:I, 2*ROW()+1), 0), IF(ISNUMBER(INDEX(Zestawienie!K:K, 2*ROW()+1)), INDEX(Zestawienie!K:K, 2*ROW()+1), 0) )-120) ) ), "" ) ) ), "")} -> 197
A5: 4 | B5: =IFERROR(__xludf.DUMMYFUNCTION("IF( OR(C5=""Zajęte"", C5=""Spóźnione""), IFERROR( INDEX( FILTER( { INDEX(Zestawienie!K:K, ROW()*2); INDEX(Zestawienie!I:I, ROW()*2); INDEX(Zestawienie!G:G, ROW()*2); INDEX(Zestawienie!E:E, ROW("&")*2); INDEX(Zestawienie!C:C, ROW()*2) }, { INDEX(Zestawienie!K:K, ROW()*2)<>"""" ; INDEX(Zestawienie!I:I, ROW()*2)<>"""" ; INDEX(Zestawienie!G:G, ROW()*2)<>"""" ; INDEX(Zestawienie!E:E, ROW"&"()*2)<>"""" ; INDEX(Zestawienie!C:C, ROW()*2)<>"""" } ), 1 ), """" ), """" ) "),"") | C5: {=IF( OR( AND(NOT(ISBLANK(INDEX(Zestawienie!C:C,ROW()*2+1))), INDEX(Zestawienie!C:C,ROW()*2+1)<TODAY()-120, ISBLANK(INDEX(Zestawienie!D:D,ROW()*2+1))), AND(NOT(ISBLANK(INDEX(Zestawienie!E:E,ROW()*2+1))), INDEX(Zestawienie!E:E,ROW()*2+1)<TODAY()-120, ISBLANK(INDEX(Zestawienie!F:F,ROW()*2+1))), AND(NOT(ISBLANK(INDEX(Zestawienie!G:G,ROW()*2+1))), INDEX(Zestawienie!G:G,ROW()*2+1)<TODAY()-120, ISBLANK(INDEX(Zestawienie!H:H,ROW()*2+1))), AND(NOT(ISBLANK(INDEX(Zestawienie!I:I,ROW()*2+1))), INDEX(Zestawienie!I:I,ROW()*2+1)<TODAY()-120, ISBLANK(INDEX(Zestawienie!J:J,ROW()*2+1))), AND(NOT(ISBLANK(INDEX(Zestawienie!K:K,ROW()*2+1))), INDEX(Zestawienie!K:K,ROW()*2+1)<TODAY()-120, ISBLANK(INDEX(Zestawienie!L:L,ROW()*2+1))) ), "Spóźnione", IF( OR( AND(NOT(ISBLANK(INDEX(Zestawienie!C:C,ROW()*2+1))), ISBLANK(INDEX(Zestawienie!D:D,ROW()*2+1))), AND(NOT(ISBLANK(INDEX(Zestawienie!E:E,ROW()*2+1))), ISBLANK(INDEX(Zestawienie!F:F,ROW()*2+1))), AND(NOT(ISBLANK(INDEX(Zestawienie!G:G,ROW()*2+1))), ISBLANK(INDEX(Zestawienie!H:H,ROW()*2+1))), AND(NOT(ISBLANK(INDEX(Zestawienie!I:I,ROW()*2+1))), ISBLANK(INDEX(Zestawienie!J:J,ROW()*2+1))), AND(NOT(ISBLANK(INDEX(Zestawienie!K:K,ROW()*2+1))), ISBLANK(INDEX(Zestawienie!L:L,ROW()*2+1))) ), "Zajęte", "Wolne" ) )} -> Wolne | D5: {=IFERROR( IF( ISBLANK(INDEX(Zestawienie!B:B, MATCH(A5, Zestawienie!A:A, 0))), "", IF(C5="Wolne", IF( OR( ISBLANK(INDEX(Zestawienie!B:B, MATCH(A5, Zestawienie!A:A, 0))), NOT(ISNUMBER(INDEX(Zestawienie!B:B, MATCH(A5, Zestawienie!A:A, 0)))) ), "", TODAY()-INDEX(Zestawienie!B:B, MATCH(A5, Zestawienie!A:A, 0)) ), IF(OR(C5="Zajęte", C5="Spóźnione"), IF( ISBLANK( MAX( IF(ISNUMBER(INDEX(Zestawienie!C:C, 2*ROW()+1)), INDEX(Zestawienie!C:C, 2*ROW()+1), 0), IF(ISNUMBER(INDEX(Zestawienie!E:E, 2*ROW()+1)), INDEX(Zestawienie!E:E, 2*ROW()+1), 0), IF(ISNUMBER(INDEX(Zestawienie!G:G, 2*ROW()+1)), INDEX(Zestawienie!G:G, 2*ROW()+1), 0), IF(ISNUMBER(INDEX(Zestawienie!I:I, 2*ROW()+1)), INDEX(Zestawienie!I:I, 2*ROW()+1), 0), IF(ISNUMBER(INDEX(Zestawienie!K:K, 2*ROW()+1)), INDEX(Zestawienie!K:K, 2*ROW()+1), 0) ) ), "", IF(C5="Zajęte", TODAY()-MAX( IF(ISNUMBER(INDEX(Zestawienie!C:C, 2*ROW()+1)), INDEX(Zestawienie!C:C, 2*ROW()+1), 0), IF(ISNUMBER(INDEX(Zestawienie!E:E, 2*ROW()+1)), INDEX(Zestawienie!E:E, 2*ROW()+1), 0), IF(ISNUMBER(INDEX(Zestawienie!G:G, 2*ROW()+1)), INDEX(Zestawienie!G:G, 2*ROW()+1), 0), IF(ISNUMBER(INDEX(Zestawienie!I:I, 2*ROW()+1)), INDEX(Zestawienie!I:I, 2*ROW()+1), 0), IF(ISNUMBER(INDEX(Zestawienie!K:K, 2*ROW()+1)), INDEX(Zestawienie!K:K, 2*ROW()+1), 0) ), MAX(0, TODAY()-MAX( IF(ISNUMBER(INDEX(Zestawienie!C:C, 2*ROW()+1)), INDEX(Zestawienie!C:C, 2*ROW()+1), 0), IF(ISNUMBER(INDEX(Zestawienie!E:E, 2*ROW()+1)), INDEX(Zestawienie!E:E, 2*ROW()+1), 0), IF(ISNUMBER(INDEX(Zestawienie!G:G, 2*ROW()+1)), INDEX(Zestawienie!G:G, 2*ROW()+1), 0), IF(ISNUMBER(INDEX(Zestawienie!I:I, 2*ROW()+1)), INDEX(Zestawienie!I:I, 2*ROW()+1), 0), IF(ISNUMBER(INDEX(Zestawienie!K:K, 2*ROW()+1)), INDEX(Zestawienie!K:K, 2*ROW()+1), 0) )-120) ) ), "" ) ) ), "")} -> 58
A6: 5 | B6: =IFERROR(__xludf.DUMMYFUNCTION("IF( OR(C6=""Zajęte"", C6=""Spóźnione""), IFERROR( INDEX( FILTER( { INDEX(Zestawienie!K:K, ROW()*2); INDEX(Zestawienie!I:I, ROW()*2); INDEX(Zestawienie!G:G, ROW()*2); INDEX(Zestawienie!E:E, ROW("&")*2); INDEX(Zestawienie!C:C, ROW()*2) }, { INDEX(Zestawienie!K:K, ROW()*2)<>"""" ; INDEX(Zestawienie!I:I, ROW()*2)<>"""" ; INDEX(Zestawienie!G:G, ROW()*2)<>"""" ; INDEX(Zestawienie!E:E, ROW"&"()*2)<>"""" ; INDEX(Zestawienie!C:C, ROW()*2)<>"""" } ), 1 ), """" ), """" ) "),"") | C6: {=IF( OR( AND(NOT(ISBLANK(INDEX(Zestawienie!C:C,ROW()*2+1))), INDEX(Zestawienie!C:C,ROW()*2+1)<TODAY()-120, ISBLANK(INDEX(Zestawienie!D:D,ROW()*2+1))), AND(NOT(ISBLANK(INDEX(Zestawienie!E:E,ROW()*2+1))), INDEX(Zestawienie!E:E,ROW()*2+1)<TODAY()-120, ISBLANK(INDEX(Zestawienie!F:F,ROW()*2+1))), AND(NOT(ISBLANK(INDEX(Zestawienie!G:G,ROW()*2+1))), INDEX(Zestawienie!G:G,ROW()*2+1)<TODAY()-120, ISBLANK(INDEX(Zestawienie!H:H,ROW()*2+1))), AND(NOT(ISBLANK(INDEX(Zestawienie!I:I,ROW()*2+1))), INDEX(Zestawienie!I:I,ROW()*2+1)<TODAY()-120, ISBLANK(INDEX(Zestawienie!J:J,ROW()*2+1))), AND(NOT(ISBLANK(INDEX(Zestawienie!K:K,ROW()*2+1))), INDEX(Zestawienie!K:K,ROW()*2+1)<TODAY()-120, ISBLANK(INDEX(Zestawienie!L:L,ROW()*2+1))) ), "Spóźnione", IF( OR( AND(NOT(ISBLANK(INDEX(Zestawienie!C:C,ROW()*2+1))), ISBLANK(INDEX(Zestawienie!D:D,ROW()*2+1))), AND(NOT(ISBLANK(INDEX(Zestawienie!E:E,ROW()*2+1))), ISBLANK(INDEX(Zestawienie!F:F,ROW()*2+1))), AND(NOT(ISBLANK(INDEX(Zestawienie!G:G,ROW()*2+1))), ISBLANK(INDEX(Zestawienie!H:H,ROW()*2+1))), AND(NOT(ISBLANK(INDEX(Zestawienie!I:I,ROW()*2+1))), ISBLANK(INDEX(Zestawienie!J:J,ROW()*2+1))), AND(NOT(ISBLANK(INDEX(Zestawienie!K:K,ROW()*2+1))), ISBLANK(INDEX(Zestawienie!L:L,ROW()*2+1))) ), "Zajęte", "Wolne" ) )} -> Wolne | D6: {=IFERROR( IF( ISBLANK(INDEX(Zestawienie!B:B, MATCH(A6, Zestawienie!A:A, 0))), "", IF(C6="Wolne", IF( OR( ISBLANK(INDEX(Zestawienie!B:B, MATCH(A6, Zestawienie!A:A, 0))), NOT(ISNUMBER(INDEX(Zestawienie!B:B, MATCH(A6, Zestawienie!A:A, 0)))) ), "", TODAY()-INDEX(Zestawienie!B:B, MATCH(A6, Zestawienie!A:A, 0)) ), IF(OR(C6="Zajęte", C6="Spóźnione"), IF( ISBLANK( MAX( IF(ISNUMBER(INDEX(Zestawienie!C:C, 2*ROW()+1)), INDEX(Zestawienie!C:C, 2*ROW()+1), 0), IF(ISNUMBER(INDEX(Zestawienie!E:E, 2*ROW()+1)), INDEX(Zestawienie!E:E, 2*ROW()+1), 0), IF(ISNUMBER(INDEX(Zestawienie!G:G, 2*ROW()+1)), INDEX(Zestawienie!G:G, 2*ROW()+1), 0), IF(ISNUMBER(INDEX(Zestawienie!I:I, 2*ROW()+1)), INDEX(Zestawienie!I:I, 2*ROW()+1), 0), IF(ISNUMBER(INDEX(Zestawienie!K:K, 2*ROW()+1)), INDEX(Zestawienie!K:K, 2*ROW()+1), 0) ) ), "", IF(C6="Zajęte", TODAY()-MAX( IF(ISNUMBER(INDEX(Zestawienie!C:C, 2*ROW()+1)), INDEX(Zestawienie!C:C, 2*ROW()+1), 0), IF(ISNUMBER(INDEX(Zestawienie!E:E, 2*ROW()+1)), INDEX(Zestawienie!E:E, 2*ROW()+1), 0), IF(ISNUMBER(INDEX(Zestawienie!G:G, 2*ROW()+1)), INDEX(Zestawienie!G:G, 2*ROW()+1), 0), IF(ISNUMBER(INDEX(Zestawienie!I:I, 2*ROW()+1)), INDEX(Zestawienie!I:I, 2*ROW()+1), 0), IF(ISNUMBER(INDEX(Zestawienie!K:K, 2*ROW()+1)), INDEX(Zestawienie!K:K, 2*ROW()+1), 0) ), MAX(0, TODAY()-MAX( IF(ISNUMBER(INDEX(Zestawienie!C:C, 2*ROW()+1)), INDEX(Zestawienie!C:C, 2*ROW()+1), 0), IF(ISNUMBER(INDEX(Zestawienie!E:E, 2*ROW()+1)), INDEX(Zestawienie!E:E, 2*ROW()+1), 0), IF(ISNUMBER(INDEX(Zestawienie!G:G, 2*ROW()+1)), INDEX(Zestawienie!G:G, 2*ROW()+1), 0), IF(ISNUMBER(INDEX(Zestawienie!I:I, 2*ROW()+1)), INDEX(Zestawienie!I:I, 2*ROW()+1), 0), IF(ISNUMBER(INDEX(Zestawienie!K:K, 2*ROW()+1)), INDEX(Zestawienie!K:K, 2*ROW()+1), 0) )-120) ) ), "" ) ) ), "")} -> 198
A7: 6 | B7: =IFERROR(__xludf.DUMMYFUNCTION("IF( OR(C7=""Zajęte"", C7=""Spóźnione""), IFERROR( INDEX( FILTER( { INDEX(Zestawienie!K:K, ROW()*2); INDEX(Zestawienie!I:I, ROW()*2); INDEX(Zestawienie!G:G, ROW()*2); INDEX(Zestawienie!E:E, ROW("&")*2); INDEX(Zestawienie!C:C, ROW()*2) }, { INDEX(Zestawienie!K:K, ROW()*2)<>"""" ; INDEX(Zestawienie!I:I, ROW()*2)<>"""" ; INDEX(Zestawienie!G:G, ROW()*2)<>"""" ; INDEX(Zestawienie!E:E, ROW"&"()*2)<>"""" ; INDEX(Zestawienie!C:C, ROW()*2)<>"""" } ), 1 ), """" ), """" ) "),"") | C7: {=IF( OR( AND(NOT(ISBLANK(INDEX(Zestawienie!C:C,ROW()*2+1))), INDEX(Zestawienie!C:C,ROW()*2+1)<TODAY()-120, ISBLANK(INDEX(Zestawienie!D:D,ROW()*2+1))), AND(NOT(ISBLANK(INDEX(Zestawienie!E:E,ROW()*2+1))), INDEX(Zestawienie!E:E,ROW()*2+1)<TODAY()-120, ISBLANK(INDEX(Zestawienie!F:F,ROW()*2+1))), AND(NOT(ISBLANK(INDEX(Zestawienie!G:G,ROW()*2+1))), INDEX(Zestawienie!G:G,ROW()*2+1)<TODAY()-120, ISBLANK(INDEX(Zestawienie!H:H,ROW()*2+1))), AND(NOT(ISBLANK(INDEX(Zestawienie!I:I,ROW()*2+1))), INDEX(Zestawienie!I:I,ROW()*2+1)<TODAY()-120, ISBLANK(INDEX(Zestawienie!J:J,ROW()*2+1))), AND(NOT(ISBLANK(INDEX(Zestawienie!K:K,ROW()*2+1))), INDEX(Zestawienie!K:K,ROW()*2+1)<TODAY()-120, ISBLANK(INDEX(Zestawienie!L:L,ROW()*2+1))) ), "Spóźnione", IF( OR( AND(NOT(ISBLANK(INDEX(Zestawienie!C:C,ROW()*2+1))), ISBLANK(INDEX(Zestawienie!D:D,ROW()*2+1))), AND(NOT(ISBLANK(INDEX(Zestawienie!E:E,ROW()*2+1))), ISBLANK(INDEX(Zestawienie!F:F,ROW()*2+1))), AND(NOT(ISBLANK(INDEX(Zestawienie!G:G,ROW()*2+1))), ISBLANK(INDEX(Zestawienie!H:H,ROW()*2+1))), AND(NOT(ISBLANK(INDEX(Zestawienie!I:I,ROW()*2+1))), ISBLANK(INDEX(Zestawienie!J:J,ROW()*2+1))), AND(NOT(ISBLANK(INDEX(Zestawienie!K:K,ROW()*2+1))), ISBLANK(INDEX(Zestawienie!L:L,ROW()*2+1))) ), "Zajęte", "Wolne" ) )} -> Wolne | D7: {=IFERROR( IF( ISBLANK(INDEX(Zestawienie!B:B, MATCH(A7, Zestawienie!A:A, 0))), "", IF(C7="Wolne", IF( OR( ISBLANK(INDEX(Zestawienie!B:B, MATCH(A7, Zestawienie!A:A, 0))), NOT(ISNUMBER(INDEX(Zestawienie!B:B, MATCH(A7, Zestawienie!A:A, 0)))) ), "", TODAY()-INDEX(Zestawienie!B:B, MATCH(A7, Zestawienie!A:A, 0)) ), IF(OR(C7="Zajęte", C7="Spóźnione"), IF( ISBLANK( MAX( IF(ISNUMBER(INDEX(Zestawienie!C:C, 2*ROW()+1)), INDEX(Zestawienie!C:C, 2*ROW()+1), 0), IF(ISNUMBER(INDEX(Zestawienie!E:E, 2*ROW()+1)), INDEX(Zestawienie!E:E, 2*ROW()+1), 0), IF(ISNUMBER(INDEX(Zestawienie!G:G, 2*ROW()+1)), INDEX(Zestawienie!G:G, 2*ROW()+1), 0), IF(ISNUMBER(INDEX(Zestawienie!I:I, 2*ROW()+1)), INDEX(Zestawienie!I:I, 2*ROW()+1), 0), IF(ISNUMBER(INDEX(Zestawienie!K:K, 2*ROW()+1)), INDEX(Zestawienie!K:K, 2*ROW()+1), 0) ) ), "", IF(C7="Zajęte", TODAY()-MAX( IF(ISNUMBER(INDEX(Zestawienie!C:C, 2*ROW()+1)), INDEX(Zestawienie!C:C, 2*ROW()+1), 0), IF(ISNUMBER(INDEX(Zestawienie!E:E, 2*ROW()+1)), INDEX(Zestawienie!E:E, 2*ROW()+1), 0), IF(ISNUMBER(INDEX(Zestawienie!G:G, 2*ROW()+1)), INDEX(Zestawienie!G:G, 2*ROW()+1), 0), IF(ISNUMBER(INDEX(Zestawienie!I:I, 2*ROW()+1)), INDEX(Zestawienie!I:I, 2*ROW()+1), 0), IF(ISNUMBER(INDEX(Zestawienie!K:K, 2*ROW()+1)), INDEX(Zestawienie!K:K, 2*ROW()+1), 0) ), MAX(0, TODAY()-MAX( IF(ISNUMBER(INDEX(Zestawienie!C:C, 2*ROW()+1)), INDEX(Zestawienie!C:C, 2*ROW()+1), 0), IF(ISNUMBER(INDEX(Zestawienie!E:E, 2*ROW()+1)), INDEX(Zestawienie!E:E, 2*ROW()+1), 0), IF(ISNUMBER(INDEX(Zestawienie!G:G, 2*ROW()+1)), INDEX(Zestawienie!G:G, 2*ROW()+1), 0), IF(ISNUMBER(INDEX(Zestawienie!I:I, 2*ROW()+1)), INDEX(Zestawienie!I:I, 2*ROW()+1), 0), IF(ISNUMBER(INDEX(Zestawienie!K:K, 2*ROW()+1)), INDEX(Zestawienie!K:K, 2*ROW()+1), 0) )-120) ) ), "" ) ) ), "")} -> 288
A8: 7 | B8: =IFERROR(__xludf.DUMMYFUNCTION("IF( OR(C8=""Zajęte"", C8=""Spóźnione""), IFERROR( INDEX( FILTER( { INDEX(Zestawienie!K:K, ROW()*2); INDEX(Zestawienie!I:I, ROW()*2); INDEX(Zestawienie!G:G, ROW()*2); INDEX(Zestawienie!E:E, ROW("&")*2); INDEX(Zestawienie!C:C, ROW()*2) }, { INDEX(Zestawienie!K:K, ROW()*2)<>"""" ; INDEX(Zestawienie!I:I, ROW()*2)<>"""" ; INDEX(Zestawienie!G:G, ROW()*2)<>"""" ; INDEX(Zestawienie!E:E, ROW"&"()*2)<>"""" ; INDEX(Zestawienie!C:C, ROW()*2)<>"""" } ), 1 ), """" ), """" ) "),"") | C8: {=IF( OR( AND(NOT(ISBLANK(INDEX(Zestawienie!C:C,ROW()*2+1))), INDEX(Zestawienie!C:C,ROW()*2+1)<TODAY()-120, ISBLANK(INDEX(Zestawienie!D:D,ROW()*2+1))), AND(NOT(ISBLANK(INDEX(Zestawienie!E:E,ROW()*2+1))), INDEX(Zestawienie!E:E,ROW()*2+1)<TODAY()-120, ISBLANK(INDEX(Zestawienie!F:F,ROW()*2+1))), AND(NOT(ISBLANK(INDEX(Zestawienie!G:G,ROW()*2+1))), INDEX(Zestawienie!G:G,ROW()*2+1)<TODAY()-120, ISBLANK(INDEX(Zestawienie!H:H,ROW()*2+1))), AND(NOT(ISBLANK(INDEX(Zestawienie!I:I,ROW()*2+1))), INDEX(Zestawienie!I:I,ROW()*2+1)<TODAY()-120, ISBLANK(INDEX(Zestawienie!J:J,ROW()*2+1))), AND(NOT(ISBLANK(INDEX(Zestawienie!K:K,ROW()*2+1))), INDEX(Zestawienie!K:K,ROW()*2+1)<TODAY()-120, ISBLANK(INDEX(Zestawienie!L:L,ROW()*2+1))) ), "Spóźnione", IF( OR( AND(NOT(ISBLANK(INDEX(Zestawienie!C:C,ROW()*2+1))), ISBLANK(INDEX(Zestawienie!D:D,ROW()*2+1))), AND(NOT(ISBLANK(INDEX(Zestawienie!E:E,ROW()*2+1))), ISBLANK(INDEX(Zestawienie!F:F,ROW()*2+1))), AND(NOT(ISBLANK(INDEX(Zestawienie!G:G,ROW()*2+1))), ISBLANK(INDEX(Zestawienie!H:H,ROW()*2+1))), AND(NOT(ISBLANK(INDEX(Zestawienie!I:I,ROW()*2+1))), ISBLANK(INDEX(Zestawienie!J:J,ROW()*2+1))), AND(NOT(ISBLANK(INDEX(Zestawienie!K:K,ROW()*2+1))), ISBLANK(INDEX(Zestawienie!L:L,ROW()*2+1))) ), "Zajęte", "Wolne" ) )} -> Wolne | D8: {=IFERROR( IF( ISBLANK(INDEX(Zestawienie!B:B, MATCH(A8, Zestawienie!A:A, 0))), "", IF(C8="Wolne", IF( OR( ISBLANK(INDEX(Zestawienie!B:B, MATCH(A8, Zestawienie!A:A, 0))), NOT(ISNUMBER(INDEX(Zestawienie!B:B, MATCH(A8, Zestawienie!A:A, 0)))) ), "", TODAY()-INDEX(Zestawienie!B:B, MATCH(A8, Zestawienie!A:A, 0)) ), IF(OR(C8="Zajęte", C8="Spóźnione"), IF( ISBLANK( MAX( IF(ISNUMBER(INDEX(Zestawienie!C:C, 2*ROW()+1)), INDEX(Zestawienie!C:C, 2*ROW()+1), 0), IF(ISNUMBER(INDEX(Zestawienie!E:E, 2*ROW()+1)), INDEX(Zestawienie!E:E, 2*ROW()+1), 0), IF(ISNUMBER(INDEX(Zestawienie!G:G, 2*ROW()+1)), INDEX(Zestawienie!G:G, 2*ROW()+1), 0), IF(ISNUMBER(INDEX(Zestawienie!I:I, 2*ROW()+1)), INDEX(Zestawienie!I:I, 2*ROW()+1), 0), IF(ISNUMBER(INDEX(Zestawienie!K:K, 2*ROW()+1)), INDEX(Zestawienie!K:K, 2*ROW()+1), 0) ) ), "", IF(C8="Zajęte", TODAY()-MAX( IF(ISNUMBER(INDEX(Zestawienie!C:C, 2*ROW()+1)), INDEX(Zestawienie!C:C, 2*ROW()+1), 0), IF(ISNUMBER(INDEX(Zestawienie!E:E, 2*ROW()+1)), INDEX(Zestawienie!E:E, 2*ROW()+1), 0), IF(ISNUMBER(INDEX(Zestawienie!G:G, 2*ROW()+1)), INDEX(Zestawienie!G:G, 2*ROW()+1), 0), IF(ISNUMBER(INDEX(Zestawienie!I:I, 2*ROW()+1)), INDEX(Zestawienie!I:I, 2*ROW()+1), 0), IF(ISNUMBER(INDEX(Zestawienie!K:K, 2*ROW()+1)), INDEX(Zestawienie!K:K, 2*ROW()+1), 0) ), MAX(0, TODAY()-MAX( IF(ISNUMBER(INDEX(Zestawienie!C:C, 2*ROW()+1)), INDEX(Zestawienie!C:C, 2*ROW()+1), 0), IF(ISNUMBER(INDEX(Zestawienie!E:E, 2*ROW()+1)), INDEX(Zestawienie!E:E, 2*ROW()+1), 0), IF(ISNUMBER(INDEX(Zestawienie!G:G, 2*ROW()+1)), INDEX(Zestawienie!G:G, 2*ROW()+1), 0), IF(ISNUMBER(INDEX(Zestawienie!I:I, 2*ROW()+1)), INDEX(Zestawienie!I:I, 2*ROW()+1), 0), IF(ISNUMBER(INDEX(Zestawienie!K:K, 2*ROW()+1)), INDEX(Zestawienie!K:K, 2*ROW()+1), 0) )-120) ) ), "" ) ) ), "")} -> 158
A9: 8 | B9: =IFERROR(__xludf.DUMMYFUNCTION("IF( OR(C9=""Zajęte"", C9=""Spóźnione""), IFERROR( INDEX( FILTER( { INDEX(Zestawienie!K:K, ROW()*2); INDEX(Zestawienie!I:I, ROW()*2); INDEX(Zestawienie!G:G, ROW()*2); INDEX(Zestawienie!E:E, ROW("&")*2); INDEX(Zestawienie!C:C, ROW()*2) }, { INDEX(Zestawienie!K:K, ROW()*2)<>"""" ; INDEX(Zestawienie!I:I, ROW()*2)<>"""" ; INDEX(Zestawienie!G:G, ROW()*2)<>"""" ; INDEX(Zestawienie!E:E, ROW"&"()*2)<>"""" ; INDEX(Zestawienie!C:C, ROW()*2)<>"""" } ), 1 ), """" ), """" ) "),"") | C9: {=IF( OR( AND(NOT(ISBLANK(INDEX(Zestawienie!C:C,ROW()*2+1))), INDEX(Zestawienie!C:C,ROW()*2+1)<TODAY()-120, ISBLANK(INDEX(Zestawienie!D:D,ROW()*2+1))), AND(NOT(ISBLANK(INDEX(Zestawienie!E:E,ROW()*2+1))), INDEX(Zestawienie!E:E,ROW()*2+1)<TODAY()-120, ISBLANK(INDEX(Zestawienie!F:F,ROW()*2+1))), AND(NOT(ISBLANK(INDEX(Zestawienie!G:G,ROW()*2+1))), INDEX(Zestawienie!G:G,ROW()*2+1)<TODAY()-120, ISBLANK(INDEX(Zestawienie!H:H,ROW()*2+1))), AND(NOT(ISBLANK(INDEX(Zestawienie!I:I,ROW()*2+1))), INDEX(Zestawienie!I:I,ROW()*2+1)<TODAY()-120, ISBLANK(INDEX(Zestawienie!J:J,ROW()*2+1))), AND(NOT(ISBLANK(INDEX(Zestawienie!K:K,ROW()*2+1))), INDEX(Zestawienie!K:K,ROW()*2+1)<TODAY()-120, ISBLANK(INDEX(Zestawienie!L:L,ROW()*2+1))) ), "Spóźnione", IF( OR( AND(NOT(ISBLANK(INDEX(Zestawienie!C:C,ROW()*2+1))), ISBLANK(INDEX(Zestawienie!D:D,ROW()*2+1))), AND(NOT(ISBLANK(INDEX(Zestawienie!E:E,ROW()*2+1))), ISBLANK(INDEX(Zestawienie!F:F,ROW()*2+1))), AND(NOT(ISBLANK(INDEX(Zestawienie!G:G,ROW()*2+1))), ISBLANK(INDEX(Zestawienie!H:H,ROW()*2+1))), AND(NOT(ISBLANK(INDEX(Zestawienie!I:I,ROW()*2+1))), ISBLANK(INDEX(Zestawienie!J:J,ROW()*2+1))), AND(NOT(ISBLANK(INDEX(Zestawienie!K:K,ROW()*2+1))), ISBLANK(INDEX(Zestawienie!L:L,ROW()*2+1))) ), "Zajęte", "Wolne" ) )} -> Wolne | D9: {=IFERROR( IF( ISBLANK(INDEX(Zestawienie!B:B, MATCH(A9, Zestawienie!A:A, 0))), "", IF(C9="Wolne", IF( OR( ISBLANK(INDEX(Zestawienie!B:B, MATCH(A9, Zestawienie!A:A, 0))), NOT(ISNUMBER(INDEX(Zestawienie!B:B, MATCH(A9, Zestawienie!A:A, 0)))) ), "", TODAY()-INDEX(Zestawienie!B:B, MATCH(A9, Zestawienie!A:A, 0)) ), IF(OR(C9="Zajęte", C9="Spóźnione"), IF( ISBLANK( MAX( IF(ISNUMBER(INDEX(Zestawienie!C:C, 2*ROW()+1)), INDEX(Zestawienie!C:C, 2*ROW()+1), 0), IF(ISNUMBER(INDEX(Zestawienie!E:E, 2*ROW()+1)), INDEX(Zestawienie!E:E, 2*ROW()+1), 0), IF(ISNUMBER(INDEX(Zestawienie!G:G, 2*ROW()+1)), INDEX(Zestawienie!G:G, 2*ROW()+1), 0), IF(ISNUMBER(INDEX(Zestawienie!I:I, 2*ROW()+1)), INDEX(Zestawienie!I:I, 2*ROW()+1), 0), IF(ISNUMBER(INDEX(Zestawienie!K:K, 2*ROW()+1)), INDEX(Zestawienie!K:K, 2*ROW()+1), 0) ) ), "", IF(C9="Zajęte", TODAY()-MAX( IF(ISNUMBER(INDEX(Zestawienie!C:C, 2*ROW()+1)), INDEX(Zestawienie!C:C, 2*ROW()+1), 0), IF(ISNUMBER(INDEX(Zestawienie!E:E, 2*ROW()+1)), INDEX(Zestawienie!E:E, 2*ROW()+1), 0), IF(ISNUMBER(INDEX(Zestawienie!G:G, 2*ROW()+1)), INDEX(Zestawienie!G:G, 2*ROW()+1), 0), IF(ISNUMBER(INDEX(Zestawienie!I:I, 2*ROW()+1)), INDEX(Zestawienie!I:I, 2*ROW()+1), 0), IF(ISNUMBER(INDEX(Zestawienie!K:K, 2*ROW()+1)), INDEX(Zestawienie!K:K, 2*ROW()+1), 0) ), MAX(0, TODAY()-MAX( IF(ISNUMBER(INDEX(Zestawienie!C:C, 2*ROW()+1)), INDEX(Zestawienie!C:C, 2*ROW()+1), 0), IF(ISNUMBER(INDEX(Zestawienie!E:E, 2*ROW()+1)), INDEX(Zestawienie!E:E, 2*ROW()+1), 0), IF(ISNUMBER(INDEX(Zestawienie!G:G, 2*ROW()+1)), INDEX(Zestawienie!G:G, 2*ROW()+1), 0), IF(ISNUMBER(INDEX(Zestawienie!I:I, 2*ROW()+1)), INDEX(Zestawienie!I:I, 2*ROW()+1), 0), IF(ISNUMBER(INDEX(Zestawienie!K:K, 2*ROW()+1)), INDEX(Zestawienie!K:K, 2*ROW()+1), 0) )-120) ) ), "" ) ) ), "")} -> 255
A10: 9 | B10: =IFERROR(__xludf.DUMMYFUNCTION("IF( OR(C10=""Zajęte"", C10=""Spóźnione""), IFERROR( INDEX( FILTER( { INDEX(Zestawienie!K:K, ROW()*2); INDEX(Zestawienie!I:I, ROW()*2); INDEX(Zestawienie!G:G, ROW()*2); INDEX(Zestawienie!E:E, RO"&"W()*2); INDEX(Zestawienie!C:C, ROW()*2) }, { INDEX(Zestawienie!K:K, ROW()*2)<>"""" ; INDEX(Zestawienie!I:I, ROW()*2)<>"""" ; INDEX(Zestawienie!G:G, ROW()*2)<>"""" ; INDEX(Zestawienie!E:E, R"&"OW()*2)<>"""" ; INDEX(Zestawienie!C:C, ROW()*2)<>"""" } ), 1 ), """" ), """" ) "),"") | C10: {=IF( OR( AND(NOT(ISBLANK(INDEX(Zestawienie!C:C,ROW()*2+1))), INDEX(Zestawienie!C:C,ROW()*2+1)<TODAY()-120, ISBLANK(INDEX(Zestawienie!D:D,ROW()*2+1))), AND(NOT(ISBLANK(INDEX(Zestawienie!E:E,ROW()*2+1))), INDEX(Zestawienie!E:E,ROW()*2+1)<TODAY()-120, ISBLANK(INDEX(Zestawienie!F:F,ROW()*2+1))), AND(NOT(ISBLANK(INDEX(Zestawienie!G:G,ROW()*2+1))), INDEX(Zestawienie!G:G,ROW()*2+1)<TODAY()-120, ISBLANK(INDEX(Zestawienie!H:H,ROW()*2+1))), AND(NOT(ISBLANK(INDEX(Zestawienie!I:I,ROW()*2+1))), INDEX(Zestawienie!I:I,ROW()*2+1)<TODAY()-120, ISBLANK(INDEX(Zestawienie!J:J,ROW()*2+1))), AND(NOT(ISBLANK(INDEX(Zestawienie!K:K,ROW()*2+1))), INDEX(Zestawienie!K:K,ROW()*2+1)<TODAY()-120, ISBLANK(INDEX(Zestawienie!L:L,ROW()*2+1))) ), "Spóźnione", IF( OR( AND(NOT(ISBLANK(INDEX(Zestawienie!C:C,ROW()*2+1))), ISBLANK(INDEX(Zestawienie!D:D,ROW()*2+1))), AND(NOT(ISBLANK(INDEX(Zestawienie!E:E,ROW()*2+1))), ISBLANK(INDEX(Zestawienie!F:F,ROW()*2+1))), AND(NOT(ISBLANK(INDEX(Zestawienie!G:G,ROW()*2+1))), ISBLANK(INDEX(Zestawienie!H:H,ROW()*2+1))), AND(NOT(ISBLANK(INDEX(Zestawienie!I:I,ROW()*2+1))), ISBLANK(INDEX(Zestawienie!J:J,ROW()*2+1))), AND(NOT(ISBLANK(INDEX(Zestawienie!K:K,ROW()*2+1))), ISBLANK(INDEX(Zestawienie!L:L,ROW()*2+1))) ), "Zajęte", "Wolne" ) )} -> Wolne | D10: {=IFERROR( IF( ISBLANK(INDEX(Zestawienie!B:B, MATCH(A10, Zestawienie!A:A, 0))), "", IF(C10="Wolne", IF( OR( ISBLANK(INDEX(Zestawienie!B:B, MATCH(A10, Zestawienie!A:A, 0))), NOT(ISNUMBER(INDEX(Zestawienie!B:B, MATCH(A10, Zestawienie!A:A, 0)))) ), "", TODAY()-INDEX(Zestawienie!B:B, MATCH(A10, Zestawienie!A:A, 0)) ), IF(OR(C10="Zajęte", C10="Spóźnione"), IF( ISBLANK( MAX( IF(ISNUMBER(INDEX(Zestawienie!C:C, 2*ROW()+1)), INDEX(Zestawienie!C:C, 2*ROW()+1), 0), IF(ISNUMBER(INDEX(Zestawienie!E:E, 2*ROW()+1)), INDEX(Zestawienie!E:E, 2*ROW()+1), 0), IF(ISNUMBER(INDEX(Zestawienie!G:G, 2*ROW()+1)), INDEX(Zestawienie!G:G, 2*ROW()+1), 0), IF(ISNUMBER(INDEX(Zestawienie!I:I, 2*ROW()+1)), INDEX(Zestawienie!I:I, 2*ROW()+1), 0), IF(ISNUMBER(INDEX(Zestawienie!K:K, 2*ROW()+1)), INDEX(Zestawienie!K:K, 2*ROW()+1), 0) ) ), "", IF(C10="Zajęte", TODAY()-MAX( IF(ISNUMBER(INDEX(Zestawienie!C:C, 2*ROW()+1)), INDEX(Zestawienie!C:C, 2*ROW()+1), 0), IF(ISNUMBER(INDEX(Zestawienie!E:E, 2*ROW()+1)), INDEX(Zestawienie!E:E, 2*ROW()+1), 0), IF(ISNUMBER(INDEX(Zestawienie!G:G, 2*ROW()+1)), INDEX(Zestawienie!G:G, 2*ROW()+1), 0), IF(ISNUMBER(INDEX(Zestawienie!I:I, 2*ROW()+1)), INDEX(Zestawienie!I:I, 2*ROW()+1), 0), IF(ISNUMBER(INDEX(Zestawienie!K:K, 2*ROW()+1)), INDEX(Zestawienie!K:K, 2*ROW()+1), 0) ), MAX(0, TODAY()-MAX( IF(ISNUMBER(INDEX(Zestawienie!C:C, 2*ROW()+1)), INDEX(Zestawienie!C:C, 2*ROW()+1), 0), IF(ISNUMBER(INDEX(Zestawienie!E:E, 2*ROW()+1)), INDEX(Zestawienie!E:E, 2*ROW()+1), 0), IF(ISNUMBER(INDEX(Zestawienie!G:G, 2*ROW()+1)), INDEX(Zestawienie!G:G, 2*ROW()+1), 0), IF(ISNUMBER(INDEX(Zestawienie!I:I, 2*ROW()+1)), INDEX(Zestawienie!I:I, 2*ROW()+1), 0), IF(ISNUMBER(INDEX(Zestawienie!K:K, 2*ROW()+1)), INDEX(Zestawienie!K:K, 2*ROW()+1), 0) )-120) ) ), "" ) ) ), "")} -> 95
A11: 10 | B11: =IFERROR(__xludf.DUMMYFUNCTION("IF( OR(C11=""Zajęte"", C11=""Spóźnione""), IFERROR( INDEX( FILTER( { INDEX(Zestawienie!K:K, ROW()*2); INDEX(Zestawienie!I:I, ROW()*2); INDEX(Zestawienie!G:G, ROW()*2); INDEX(Zestawienie!E:E, RO"&"W()*2); INDEX(Zestawienie!C:C, ROW()*2) }, { INDEX(Zestawienie!K:K, ROW()*2)<>"""" ; INDEX(Zestawienie!I:I, ROW()*2)<>"""" ; INDEX(Zestawienie!G:G, ROW()*2)<>"""" ; INDEX(Zestawienie!E:E, R"&"OW()*2)<>"""" ; INDEX(Zestawienie!C:C, ROW()*2)<>"""" } ), 1 ), """" ), """" ) "),"") | C11: {=IF( OR( AND(NOT(ISBLANK(INDEX(Zestawienie!C:C,ROW()*2+1))), INDEX(Zestawienie!C:C,ROW()*2+1)<TODAY()-120, ISBLANK(INDEX(Zestawienie!D:D,ROW()*2+1))), AND(NOT(ISBLANK(INDEX(Zestawienie!E:E,ROW()*2+1))), INDEX(Zestawienie!E:E,ROW()*2+1)<TODAY()-120, ISBLANK(INDEX(Zestawienie!F:F,ROW()*2+1))), AND(NOT(ISBLANK(INDEX(Zestawienie!G:G,ROW()*2+1))), INDEX(Zestawienie!G:G,ROW()*2+1)<TODAY()-120, ISBLANK(INDEX(Zestawienie!H:H,ROW()*2+1))), AND(NOT(ISBLANK(INDEX(Zestawienie!I:I,ROW()*2+1))), INDEX(Zestawienie!I:I,ROW()*2+1)<TODAY()-120, ISBLANK(INDEX(Zestawienie!J:J,ROW()*2+1))), AND(NOT(ISBLANK(INDEX(Zestawienie!K:K,ROW()*2+1))), INDEX(Zestawienie!K:K,ROW()*2+1)<TODAY()-120, ISBLANK(INDEX(Zestawienie!L:L,ROW()*2+1))) ), "Spóźnione", IF( OR( AND(NOT(ISBLANK(INDEX(Zestawienie!C:C,ROW()*2+1))), ISBLANK(INDEX(Zestawienie!D:D,ROW()*2+1))), AND(NOT(ISBLANK(INDEX(Zestawienie!E:E,ROW()*2+1))), ISBLANK(INDEX(Zestawienie!F:F,ROW()*2+1))), AND(NOT(ISBLANK(INDEX(Zestawienie!G:G,ROW()*2+1))), ISBLANK(INDEX(Zestawienie!H:H,ROW()*2+1))), AND(NOT(ISBLANK(INDEX(Zestawienie!I:I,ROW()*2+1))), ISBLANK(INDEX(Zestawienie!J:J,ROW()*2+1))), AND(NOT(ISBLANK(INDEX(Zestawienie!K:K,ROW()*2+1))), ISBLANK(INDEX(Zestawienie!L:L,ROW()*2+1))) ), "Zajęte", "Wolne" ) )} -> Wolne | D11: {=IFERROR( IF( ISBLANK(INDEX(Zestawienie!B:B, MATCH(A11, Zestawienie!A:A, 0))), "", IF(C11="Wolne", IF( OR( ISBLANK(INDEX(Zestawienie!B:B, MATCH(A11, Zestawienie!A:A, 0))), NOT(ISNUMBER(INDEX(Zestawienie!B:B, MATCH(A11, Zestawienie!A:A, 0)))) ), "", TODAY()-INDEX(Zestawienie!B:B, MATCH(A11, Zestawienie!A:A, 0)) ), IF(OR(C11="Zajęte", C11="Spóźnione"), IF( ISBLANK( MAX( IF(ISNUMBER(INDEX(Zestawienie!C:C, 2*ROW()+1)), INDEX(Zestawienie!C:C, 2*ROW()+1), 0), IF(ISNUMBER(INDEX(Zestawienie!E:E, 2*ROW()+1)), INDEX(Zestawienie!E:E, 2*ROW()+1), 0), IF(ISNUMBER(INDEX(Zestawienie!G:G, 2*ROW()+1)), INDEX(Zestawienie!G:G, 2*ROW()+1), 0), IF(ISNUMBER(INDEX(Zestawienie!I:I, 2*ROW()+1)), INDEX(Zestawienie!I:I, 2*ROW()+1), 0), IF(ISNUMBER(INDEX(Zestawienie!K:K, 2*ROW()+1)), INDEX(Zestawienie!K:K, 2*ROW()+1), 0) ) ), "", IF(C11="Zajęte", TODAY()-MAX( IF(ISNUMBER(INDEX(Zestawienie!C:C, 2*ROW()+1)), INDEX(Zestawienie!C:C, 2*ROW()+1), 0), IF(ISNUMBER(INDEX(Zestawienie!E:E, 2*ROW()+1)), INDEX(Zestawienie!E:E, 2*ROW()+1), 0), IF(ISNUMBER(INDEX(Zestawienie!G:G, 2*ROW()+1)), INDEX(Zestawienie!G:G, 2*ROW()+1), 0), IF(ISNUMBER(INDEX(Zestawienie!I:I, 2*ROW()+1)), INDEX(Zestawienie!I:I, 2*ROW()+1), 0), IF(ISNUMBER(INDEX(Zestawienie!K:K, 2*ROW()+1)), INDEX(Zestawienie!K:K, 2*ROW()+1), 0) ), MAX(0, TODAY()-MAX( IF(ISNUMBER(INDEX(Zestawienie!C:C, 2*ROW()+1)), INDEX(Zestawienie!C:C, 2*ROW()+1), 0), IF(ISNUMBER(INDEX(Zestawienie!E:E, 2*ROW()+1)), INDEX(Zestawienie!E:E, 2*ROW()+1), 0), IF(ISNUMBER(INDEX(Zestawienie!G:G, 2*ROW()+1)), INDEX(Zestawienie!G:G, 2*ROW()+1), 0), IF(ISNUMBER(INDEX(Zestawienie!I:I, 2*ROW()+1)), INDEX(Zestawienie!I:I, 2*ROW()+1), 0), IF(ISNUMBER(INDEX(Zestawienie!K:K, 2*ROW()+1)), INDEX(Zestawienie!K:K, 2*ROW()+1), 0) )-120) ) ), "" ) ) ), "")} -> 93
A12: 11 | B12: =IFERROR(__xludf.DUMMYFUNCTION("IF( OR(C12=""Zajęte"", C12=""Spóźnione""), IFERROR( INDEX( FILTER( { INDEX(Zestawienie!K:K, ROW()*2); INDEX(Zestawienie!I:I, ROW()*2); INDEX(Zestawienie!G:G, ROW()*2); INDEX(Zestawienie!E:E, RO"&"W()*2); INDEX(Zestawienie!C:C, ROW()*2) }, { INDEX(Zestawienie!K:K, ROW()*2)<>"""" ; INDEX(Zestawienie!I:I, ROW()*2)<>"""" ; INDEX(Zestawienie!G:G, ROW()*2)<>"""" ; INDEX(Zestawienie!E:E, R"&"OW()*2)<>"""" ; INDEX(Zestawienie!C:C, ROW()*2)<>"""" } ), 1 ), """" ), """" ) "),"") | C12: {=IF( OR( AND(NOT(ISBLANK(INDEX(Zestawienie!C:C,ROW()*2+1))), INDEX(Zestawienie!C:C,ROW()*2+1)<TODAY()-120, ISBLANK(INDEX(Zestawienie!D:D,ROW()*2+1))), AND(NOT(ISBLANK(INDEX(Zestawienie!E:E,ROW()*2+1))), INDEX(Zestawienie!E:E,ROW()*2+1)<TODAY()-120, ISBLANK(INDEX(Zestawienie!F:F,ROW()*2+1))), AND(NOT(ISBLANK(INDEX(Zestawienie!G:G,ROW()*2+1))), INDEX(Zestawienie!G:G,ROW()*2+1)<TODAY()-120, ISBLANK(INDEX(Zestawienie!H:H,ROW()*2+1))), AND(NOT(ISBLANK(INDEX(Zestawienie!I:I,ROW()*2+1))), INDEX(Zestawienie!I:I,ROW()*2+1)<TODAY()-120, ISBLANK(INDEX(Zestawienie!J:J,ROW()*2+1))), AND(NOT(ISBLANK(INDEX(Zestawienie!K:K,ROW()*2+1))), INDEX(Zestawienie!K:K,ROW()*2+1)<TODAY()-120, ISBLANK(INDEX(Zestawienie!L:L,ROW()*2+1))) ), "Spóźnione", IF( OR( AND(NOT(ISBLANK(INDEX(Zestawienie!C:C,ROW()*2+1))), ISBLANK(INDEX(Zestawienie!D:D,ROW()*2+1))), AND(NOT(ISBLANK(INDEX(Zestawienie!E:E,ROW()*2+1))), ISBLANK(INDEX(Zestawienie!F:F,ROW()*2+1))), AND(NOT(ISBLANK(INDEX(Zestawienie!G:G,ROW()*2+1))), ISBLANK(INDEX(Zestawienie!H:H,ROW()*2+1))), AND(NOT(ISBLANK(INDEX(Zestawienie!I:I,ROW()*2+1))), ISBLANK(INDEX(Zestawienie!J:J,ROW()*2+1))), AND(NOT(ISBLANK(INDEX(Zestawienie!K:K,ROW()*2+1))), ISBLANK(INDEX(Zestawienie!L:L,ROW()*2+1))) ), "Zajęte", "Wolne" ) )} -> Wolne | D12: {=IFERROR( IF( ISBLANK(INDEX(Zestawienie!B:B, MATCH(A12, Zestawienie!A:A, 0))), "", IF(C12="Wolne", IF( OR( ISBLANK(INDEX(Zestawienie!B:B, MATCH(A12, Zestawienie!A:A, 0))), NOT(ISNUMBER(INDEX(Zestawienie!B:B, MATCH(A12, Zestawienie!A:A, 0)))) ), "", TODAY()-INDEX(Zestawienie!B:B, MATCH(A12, Zestawienie!A:A, 0)) ), IF(OR(C12="Zajęte", C12="Spóźnione"), IF( ISBLANK( MAX( IF(ISNUMBER(INDEX(Zestawienie!C:C, 2*ROW()+1)), INDEX(Zestawienie!C:C, 2*ROW()+1), 0), IF(ISNUMBER(INDEX(Zestawienie!E:E, 2*ROW()+1)), INDEX(Zestawienie!E:E, 2*ROW()+1), 0), IF(ISNUMBER(INDEX(Zestawienie!G:G, 2*ROW()+1)), INDEX(Zestawienie!G:G, 2*ROW()+1), 0), IF(ISNUMBER(INDEX(Zestawienie!I:I, 2*ROW()+1)), INDEX(Zestawienie!I:I, 2*ROW()+1), 0), IF(ISNUMBER(INDEX(Zestawienie!K:K, 2*ROW()+1)), INDEX(Zestawienie!K:K, 2*ROW()+1), 0) ) ), "", IF(C12="Zajęte", TODAY()-MAX( IF(ISNUMBER(INDEX(Zestawienie!C:C, 2*ROW()+1)), INDEX(Zestawienie!C:C, 2*ROW()+1), 0), IF(ISNUMBER(INDEX(Zestawienie!E:E, 2*ROW()+1)), INDEX(Zestawienie!E:E, 2*ROW()+1), 0), IF(ISNUMBER(INDEX(Zestawienie!G:G, 2*ROW()+1)), INDEX(Zestawienie!G:G, 2*ROW()+1), 0), IF(ISNUMBER(INDEX(Zestawienie!I:I, 2*ROW()+1)), INDEX(Zestawienie!I:I, 2*ROW()+1), 0), IF(ISNUMBER(INDEX(Zestawienie!K:K, 2*ROW()+1)), INDEX(Zestawienie!K:K, 2*ROW()+1), 0) ), MAX(0, TODAY()-MAX( IF(ISNUMBER(INDEX(Zestawienie!C:C, 2*ROW()+1)), INDEX(Zestawienie!C:C, 2*ROW()+1), 0), IF(ISNUMBER(INDEX(Zestawienie!E:E, 2*ROW()+1)), INDEX(Zestawienie!E:E, 2*ROW()+1), 0), IF(ISNUMBER(INDEX(Zestawienie!G:G, 2*ROW()+1)), INDEX(Zestawienie!G:G, 2*ROW()+1), 0), IF(ISNUMBER(INDEX(Zestawienie!I:I, 2*ROW()+1)), INDEX(Zestawienie!I:I, 2*ROW()+1), 0), IF(ISNUMBER(INDEX(Zestawienie!K:K, 2*ROW()+1)), INDEX(Zestawienie!K:K, 2*ROW()+1), 0) )-120) ) ), "" ) ) ), "")} -> 92
A13: 12 | B13: =IFERROR(__xludf.DUMMYFUNCTION("IF( OR(C13=""Zajęte"", C13=""Spóźnione""), IFERROR( INDEX( FILTER( { INDEX(Zestawienie!K:K, ROW()*2); INDEX(Zestawienie!I:I, ROW()*2); INDEX(Zestawienie!G:G, ROW()*2); INDEX(Zestawienie!E:E, RO"&"W()*2); INDEX(Zestawienie!C:C, ROW()*2) }, { INDEX(Zestawienie!K:K, ROW()*2)<>"""" ; INDEX(Zestawienie!I:I, ROW()*2)<>"""" ; INDEX(Zestawienie!G:G, ROW()*2)<>"""" ; INDEX(Zestawienie!E:E, R"&"OW()*2)<>"""" ; INDEX(Zestawienie!C:C, ROW()*2)<>"""" } ), 1 ), """" ), """" ) "),"Migrała Wioletta") -> Migrała Wioletta | C13: {=IF( OR( AND(NOT(ISBLANK(INDEX(Zestawienie!C:C,ROW()*2+1))), INDEX(Zestawienie!C:C,ROW()*2+1)<TODAY()-120, ISBLANK(INDEX(Zestawienie!D:D,ROW()*2+1))), AND(NOT(ISBLANK(INDEX(Zestawienie!E:E,ROW()*2+1))), INDEX(Zestawienie!E:E,ROW()*2+1)<TODAY()-120, ISBLANK(INDEX(Zestawienie!F:F,ROW()*2+1))), AND(NOT(ISBLANK(INDEX(Zestawienie!G:G,ROW()*2+1))), INDEX(Zestawienie!G:G,ROW()*2+1)<TODAY()-120, ISBLANK(INDEX(Zestawienie!H:H,ROW()*2+1))), AND(NOT(ISBLANK(INDEX(Zestawienie!I:I,ROW()*2+1))), INDEX(Zestawienie!I:I,ROW()*2+1)<TODAY()-120, ISBLANK(INDEX(Zestawienie!J:J,ROW()*2+1))), AND(NOT(ISBLANK(INDEX(Zestawienie!K:K,ROW()*2+1))), INDEX(Zestawienie!K:K,ROW()*2+1)<TODAY()-120, ISBLANK(INDEX(Zestawienie!L:L,ROW()*2+1))) ), "Spóźnione", IF( OR( AND(NOT(ISBLANK(INDEX(Zestawienie!C:C,ROW()*2+1))), ISBLANK(INDEX(Zestawienie!D:D,ROW()*2+1))), AND(NOT(ISBLANK(INDEX(Zestawienie!E:E,ROW()*2+1))), ISBLANK(INDEX(Zestawienie!F:F,ROW()*2+1))), AND(NOT(ISBLANK(INDEX(Zestawienie!G:G,ROW()*2+1))), ISBLANK(INDEX(Zestawienie!H:H,ROW()*2+1))), AND(NOT(ISBLANK(INDEX(Zestawienie!I:I,ROW()*2+1))), ISBLANK(INDEX(Zestawienie!J:J,ROW()*2+1))), AND(NOT(ISBLANK(INDEX(Zestawienie!K:K,ROW()*2+1))), ISBLANK(INDEX(Zestawienie!L:L,ROW()*2+1))) ), "Zajęte", "Wolne" ) )} -> Spóźnione | D13: {=IFERROR( IF( ISBLANK(INDEX(Zestawienie!B:B, MATCH(A13, Zestawienie!A:A, 0))), "", IF(C13="Wolne", IF( OR( ISBLANK(INDEX(Zestawienie!B:B, MATCH(A13, Zestawienie!A:A, 0))), NOT(ISNUMBER(INDEX(Zestawienie!B:B, MATCH(A13, Zestawienie!A:A, 0)))) ), "", TODAY()-INDEX(Zestawienie!B:B, MATCH(A13, Zestawienie!A:A, 0)) ), IF(OR(C13="Zajęte", C13="Spóźnione"), IF( ISBLANK( MAX( IF(ISNUMBER(INDEX(Zestawienie!C:C, 2*ROW()+1)), INDEX(Zestawienie!C:C, 2*ROW()+1), 0), IF(ISNUMBER(INDEX(Zestawienie!E:E, 2*ROW()+1)), INDEX(Zestawienie!E:E, 2*ROW()+1), 0), IF(ISNUMBER(INDEX(Zestawienie!G:G, 2*ROW()+1)), INDEX(Zestawienie!G:G, 2*ROW()+1), 0), IF(ISNUMBER(INDEX(Zestawienie!I:I, 2*ROW()+1)), INDEX(Zestawienie!I:I, 2*ROW()+1), 0), IF(ISNUMBER(INDEX(Zestawienie!K:K, 2*ROW()+1)), INDEX(Zestawienie!K:K, 2*ROW()+1), 0) ) ), "", IF(C13="Zajęte", TODAY()-MAX( IF(ISNUMBER(INDEX(Zestawienie!C:C, 2*ROW()+1)), INDEX(Zestawienie!C:C, 2*ROW()+1), 0), IF(ISNUMBER(INDEX(Zestawienie!E:E, 2*ROW()+1)), INDEX(Zestawienie!E:E, 2*ROW()+1), 0), IF(ISNUMBER(INDEX(Zestawienie!G:G, 2*ROW()+1)), INDEX(Zestawienie!G:G, 2*ROW()+1), 0), IF(ISNUMBER(INDEX(Zestawienie!I:I, 2*ROW()+1)), INDEX(Zestawienie!I:I, 2*ROW()+1), 0), IF(ISNUMBER(INDEX(Zestawienie!K:K, 2*ROW()+1)), INDEX(Zestawienie!K:K, 2*ROW()+1), 0) ), MAX(0, TODAY()-MAX( IF(ISNUMBER(INDEX(Zestawienie!C:C, 2*ROW()+1)), INDEX(Zestawienie!C:C, 2*ROW()+1), 0), IF(ISNUMBER(INDEX(Zestawienie!E:E, 2*ROW()+1)), INDEX(Zestawienie!E:E, 2*ROW()+1), 0), IF(ISNUMBER(INDEX(Zestawienie!G:G, 2*ROW()+1)), INDEX(Zestawienie!G:G, 2*ROW()+1), 0), IF(ISNUMBER(INDEX(Zestawienie!I:I, 2*ROW()+1)), INDEX(Zestawienie!I:I, 2*ROW()+1), 0), IF(ISNUMBER(INDEX(Zestawienie!K:K, 2*ROW()+1)), INDEX(Zestawienie!K:K, 2*ROW()+1), 0) )-120) ) ), "" ) ) ), "")} -> 26
A14: 13 | B14: =IFERROR(__xludf.DUMMYFUNCTION("IF( OR(C14=""Zajęte"", C14=""Spóźnione""), IFERROR( INDEX( FILTER( { INDEX(Zestawienie!K:K, ROW()*2); INDEX(Zestawienie!I:I, ROW()*2); INDEX(Zestawienie!G:G, ROW()*2); INDEX(Zestawienie!E:E, RO"&"W()*2); INDEX(Zestawienie!C:C, ROW()*2) }, { INDEX(Zestawienie!K:K, ROW()*2)<>"""" ; INDEX(Zestawienie!I:I, ROW()*2)<>"""" ; INDEX(Zestawienie!G:G, ROW()*2)<>"""" ; INDEX(Zestawienie!E:E, R"&"OW()*2)<>"""" ; INDEX(Zestawienie!C:C, ROW()*2)<>"""" } ), 1 ), """" ), """" ) "),"") | C14: {=IF( OR( AND(NOT(ISBLANK(INDEX(Zestawienie!C:C,ROW()*2+1))), INDEX(Zestawienie!C:C,ROW()*2+1)<TODAY()-120, ISBLANK(INDEX(Zestawienie!D:D,ROW()*2+1))), AND(NOT(ISBLANK(INDEX(Zestawienie!E:E,ROW()*2+1))), INDEX(Zestawienie!E:E,ROW()*2+1)<TODAY()-120, ISBLANK(INDEX(Zestawienie!F:F,ROW()*2+1))), AND(NOT(ISBLANK(INDEX(Zestawienie!G:G,ROW()*2+1))), INDEX(Zestawienie!G:G,ROW()*2+1)<TODAY()-120, ISBLANK(INDEX(Zestawienie!H:H,ROW()*2+1))), AND(NOT(ISBLANK(INDEX(Zestawienie!I:I,ROW()*2+1))), INDEX(Zestawienie!I:I,ROW()*2+1)<TODAY()-120, ISBLANK(INDEX(Zestawienie!J:J,ROW()*2+1))), AND(NOT(ISBLANK(INDEX(Zestawienie!K:K,ROW()*2+1))), INDEX(Zestawienie!K:K,ROW()*2+1)<TODAY()-120, ISBLANK(INDEX(Zestawienie!L:L,ROW()*2+1))) ), "Spóźnione", IF( OR( AND(NOT(ISBLANK(INDEX(Zestawienie!C:C,ROW()*2+1))), ISBLANK(INDEX(Zestawienie!D:D,ROW()*2+1))), AND(NOT(ISBLANK(INDEX(Zestawienie!E:E,ROW()*2+1))), ISBLANK(INDEX(Zestawienie!F:F,ROW()*2+1))), AND(NOT(ISBLANK(INDEX(Zestawienie!G:G,ROW()*2+1))), ISBLANK(INDEX(Zestawienie!H:H,ROW()*2+1))), AND(NOT(ISBLANK(INDEX(Zestawienie!I:I,ROW()*2+1))), ISBLANK(INDEX(Zestawienie!J:J,ROW()*2+1))), AND(NOT(ISBLANK(INDEX(Zestawienie!K:K,ROW()*2+1))), ISBLANK(INDEX(Zestawienie!L:L,ROW()*2+1))) ), "Zajęte", "Wolne" ) )} -> Wolne | D14: {=IFERROR( IF( ISBLANK(INDEX(Zestawienie!B:B, MATCH(A14, Zestawienie!A:A, 0))), "", IF(C14="Wolne", IF( OR( ISBLANK(INDEX(Zestawienie!B:B, MATCH(A14, Zestawienie!A:A, 0))), NOT(ISNUMBER(INDEX(Zestawienie!B:B, MATCH(A14, Zestawienie!A:A, 0)))) ), "", TODAY()-INDEX(Zestawienie!B:B, MATCH(A14, Zestawienie!A:A, 0)) ), IF(OR(C14="Zajęte", C14="Spóźnione"), IF( ISBLANK( MAX( IF(ISNUMBER(INDEX(Zestawienie!C:C, 2*ROW()+1)), INDEX(Zestawienie!C:C, 2*ROW()+1), 0), IF(ISNUMBER(INDEX(Zestawienie!E:E, 2*ROW()+1)), INDEX(Zestawienie!E:E, 2*ROW()+1), 0), IF(ISNUMBER(INDEX(Zestawienie!G:G, 2*ROW()+1)), INDEX(Zestawienie!G:G, 2*ROW()+1), 0), IF(ISNUMBER(INDEX(Zestawienie!I:I, 2*ROW()+1)), INDEX(Zestawienie!I:I, 2*ROW()+1), 0), IF(ISNUMBER(INDEX(Zestawienie!K:K, 2*ROW()+1)), INDEX(Zestawienie!K:K, 2*ROW()+1), 0) ) ), "", IF(C14="Zajęte", TODAY()-MAX( IF(ISNUMBER(INDEX(Zestawienie!C:C, 2*ROW()+1)), INDEX(Zestawienie!C:C, 2*ROW()+1), 0), IF(ISNUMBER(INDEX(Zestawienie!E:E, 2*ROW()+1)), INDEX(Zestawienie!E:E, 2*ROW()+1), 0), IF(ISNUMBER(INDEX(Zestawienie!G:G, 2*ROW()+1)), INDEX(Zestawienie!G:G, 2*ROW()+1), 0), IF(ISNUMBER(INDEX(Zestawienie!I:I, 2*ROW()+1)), INDEX(Zestawienie!I:I, 2*ROW()+1), 0), IF(ISNUMBER(INDEX(Zestawienie!K:K, 2*ROW()+1)), INDEX(Zestawienie!K:K, 2*ROW()+1), 0) ), MAX(0, TODAY()-MAX( IF(ISNUMBER(INDEX(Zestawienie!C:C, 2*ROW()+1)), INDEX(Zestawienie!C:C, 2*ROW()+1), 0), IF(ISNUMBER(INDEX(Zestawienie!E:E, 2*ROW()+1)), INDEX(Zestawienie!E:E, 2*ROW()+1), 0), IF(ISNUMBER(INDEX(Zestawienie!G:G, 2*ROW()+1)), INDEX(Zestawienie!G:G, 2*ROW()+1), 0), IF(ISNUMBER(INDEX(Zestawienie!I:I, 2*ROW()+1)), INDEX(Zestawienie!I:I, 2*ROW()+1), 0), IF(ISNUMBER(INDEX(Zestawienie!K:K, 2*ROW()+1)), INDEX(Zestawienie!K:K, 2*ROW()+1), 0) )-120) ) ), "" ) ) ), "")} -> 104
A15: 14 | B15: =IFERROR(__xludf.DUMMYFUNCTION("IF( OR(C15=""Zajęte"", C15=""Spóźnione""), IFERROR( INDEX( FILTER( { INDEX(Zestawienie!K:K, ROW()*2); INDEX(Zestawienie!I:I, ROW()*2); INDEX(Zestawienie!G:G, ROW()*2); INDEX(Zestawienie!E:E, RO"&"W()*2); INDEX(Zestawienie!C:C, ROW()*2) }, { INDEX(Zestawienie!K:K, ROW()*2)<>"""" ; INDEX(Zestawienie!I:I, ROW()*2)<>"""" ; INDEX(Zestawienie!G:G, ROW()*2)<>"""" ; INDEX(Zestawienie!E:E, R"&"OW()*2)<>"""" ; INDEX(Zestawienie!C:C, ROW()*2)<>"""" } ), 1 ), """" ), """" ) "),"") | C15: {=IF( OR( AND(NOT(ISBLANK(INDEX(Zestawienie!C:C,ROW()*2+1))), INDEX(Zestawienie!C:C,ROW()*2+1)<TODAY()-120, ISBLANK(INDEX(Zestawienie!D:D,ROW()*2+1))), AND(NOT(ISBLANK(INDEX(Zestawienie!E:E,ROW()*2+1))), INDEX(Zestawienie!E:E,ROW()*2+1)<TODAY()-120, ISBLANK(INDEX(Zestawienie!F:F,ROW()*2+1))), AND(NOT(ISBLANK(INDEX(Zestawienie!G:G,ROW()*2+1))), INDEX(Zestawienie!G:G,ROW()*2+1)<TODAY()-120, ISBLANK(INDEX(Zestawienie!H:H,ROW()*2+1))), AND(NOT(ISBLANK(INDEX(Zestawienie!I:I,ROW()*2+1))), INDEX(Zestawienie!I:I,ROW()*2+1)<TODAY()-120, ISBLANK(INDEX(Zestawienie!J:J,ROW()*2+1))), AND(NOT(ISBLANK(INDEX(Zestawienie!K:K,ROW()*2+1))), INDEX(Zestawienie!K:K,ROW()*2+1)<TODAY()-120, ISBLANK(INDEX(Zestawienie!L:L,ROW()*2+1))) ), "Spóźnione", IF( OR( AND(NOT(ISBLANK(INDEX(Zestawienie!C:C,ROW()*2+1))), ISBLANK(INDEX(Zestawienie!D:D,ROW()*2+1))), AND(NOT(ISBLANK(INDEX(Zestawienie!E:E,ROW()*2+1))), ISBLANK(INDEX(Zestawienie!F:F,ROW()*2+1))), AND(NOT(ISBLANK(INDEX(Zestawienie!G:G,ROW()*2+1))), ISBLANK(INDEX(Zestawienie!H:H,ROW()*2+1))), AND(NOT(ISBLANK(INDEX(Zestawienie!I:I,ROW()*2+1))), ISBLANK(INDEX(Zestawienie!J:J,ROW()*2+1))), AND(NOT(ISBLANK(INDEX(Zestawienie!K:K,ROW()*2+1))), ISBLANK(INDEX(Zestawienie!L:L,ROW()*2+1))) ), "Zajęte", "Wolne" ) )} -> Wolne | D15: {=IFERROR( IF( ISBLANK(INDEX(Zestawienie!B:B, MATCH(A15, Zestawienie!A:A, 0))), "", IF(C15="Wolne", IF( OR( ISBLANK(INDEX(Zestawienie!B:B, MATCH(A15, Zestawienie!A:A, 0))), NOT(ISNUMBER(INDEX(Zestawienie!B:B, MATCH(A15, Zestawienie!A:A, 0)))) ), "", TODAY()-INDEX(Zestawienie!B:B, MATCH(A15, Zestawienie!A:A, 0)) ), IF(OR(C15="Zajęte", C15="Spóźnione"), IF( ISBLANK( MAX( IF(ISNUMBER(INDEX(Zestawienie!C:C, 2*ROW()+1)), INDEX(Zestawienie!C:C, 2*ROW()+1), 0), IF(ISNUMBER(INDEX(Zestawienie!E:E, 2*ROW()+1)), INDEX(Zestawienie!E:E, 2*ROW()+1), 0), IF(ISNUMBER(INDEX(Zestawienie!G:G, 2*ROW()+1)), INDEX(Zestawienie!G:G, 2*ROW()+1), 0), IF(ISNUMBER(INDEX(Zestawienie!I:I, 2*ROW()+1)), INDEX(Zestawienie!I:I, 2*ROW()+1), 0), IF(ISNUMBER(INDEX(Zestawienie!K:K, 2*ROW()+1)), INDEX(Zestawienie!K:K, 2*ROW()+1), 0) ) ), "", IF(C15="Zajęte", TODAY()-MAX( IF(ISNUMBER(INDEX(Zestawienie!C:C, 2*ROW()+1)), INDEX(Zestawienie!C:C, 2*ROW()+1), 0), IF(ISNUMBER(INDEX(Zestawienie!E:E, 2*ROW()+1)), INDEX(Zestawienie!E:E, 2*ROW()+1), 0), IF(ISNUMBER(INDEX(Zestawienie!G:G, 2*ROW()+1)), INDEX(Zestawienie!G:G, 2*ROW()+1), 0), IF(ISNUMBER(INDEX(Zestawienie!I:I, 2*ROW()+1)), INDEX(Zestawienie!I:I, 2*ROW()+1), 0), IF(ISNUMBER(INDEX(Zestawienie!K:K, 2*ROW()+1)), INDEX(Zestawienie!K:K, 2*ROW()+1), 0) ), MAX(0, TODAY()-MAX( IF(ISNUMBER(INDEX(Zestawienie!C:C, 2*ROW()+1)), INDEX(Zestawienie!C:C, 2*ROW()+1), 0), IF(ISNUMBER(INDEX(Zestawienie!E:E, 2*ROW()+1)), INDEX(Zestawienie!E:E, 2*ROW()+1), 0), IF(ISNUMBER(INDEX(Zestawienie!G:G, 2*ROW()+1)), INDEX(Zestawienie!G:G, 2*ROW()+1), 0), IF(ISNUMBER(INDEX(Zestawienie!I:I, 2*ROW()+1)), INDEX(Zestawienie!I:I, 2*ROW()+1), 0), IF(ISNUMBER(INDEX(Zestawienie!K:K, 2*ROW()+1)), INDEX(Zestawienie!K:K, 2*ROW()+1), 0) )-120) ) ), "" ) ) ), "")} -> 93
A16: 15 | B16: =IFERROR(__xludf.DUMMYFUNCTION("IF( OR(C16=""Zajęte"", C16=""Spóźnione""), IFERROR( INDEX( FILTER( { INDEX(Zestawienie!K:K, ROW()*2); INDEX(Zestawienie!I:I, ROW()*2); INDEX(Zestawienie!G:G, ROW()*2); INDEX(Zestawienie!E:E, RO"&"W()*2); INDEX(Zestawienie!C:C, ROW()*2) }, { INDEX(Zestawienie!K:K, ROW()*2)<>"""" ; INDEX(Zestawienie!I:I, ROW()*2)<>"""" ; INDEX(Zestawienie!G:G, ROW()*2)<>"""" ; INDEX(Zestawienie!E:E, R"&"OW()*2)<>"""" ; INDEX(Zestawienie!C:C, ROW()*2)<>"""" } ), 1 ), """" ), """" ) "),"") | C16: {=IF( OR( AND(NOT(ISBLANK(INDEX(Zestawienie!C:C,ROW()*2+1))), INDEX(Zestawienie!C:C,ROW()*2+1)<TODAY()-120, ISBLANK(INDEX(Zestawienie!D:D,ROW()*2+1))), AND(NOT(ISBLANK(INDEX(Zestawienie!E:E,ROW()*2+1))), INDEX(Zestawienie!E:E,ROW()*2+1)<TODAY()-120, ISBLANK(INDEX(Zestawienie!F:F,ROW()*2+1))), AND(NOT(ISBLANK(INDEX(Zestawienie!G:G,ROW()*2+1))), INDEX(Zestawienie!G:G,ROW()*2+1)<TODAY()-120, ISBLANK(INDEX(Zestawienie!H:H,ROW()*2+1))), AND(NOT(ISBLANK(INDEX(Zestawienie!I:I,ROW()*2+1))), INDEX(Zestawienie!I:I,ROW()*2+1)<TODAY()-120, ISBLANK(INDEX(Zestawienie!J:J,ROW()*2+1))), AND(NOT(ISBLANK(INDEX(Zestawienie!K:K,ROW()*2+1))), INDEX(Zestawienie!K:K,ROW()*2+1)<TODAY()-120, ISBLANK(INDEX(Zestawienie!L:L,ROW()*2+1))) ), "Spóźnione", IF( OR( AND(NOT(ISBLANK(INDEX(Zestawienie!C:C,ROW()*2+1))), ISBLANK(INDEX(Zestawienie!D:D,ROW()*2+1))), AND(NOT(ISBLANK(INDEX(Zestawienie!E:E,ROW()*2+1))), ISBLANK(INDEX(Zestawienie!F:F,ROW()*2+1))), AND(NOT(ISBLANK(INDEX(Zestawienie!G:G,ROW()*2+1))), ISBLANK(INDEX(Zestawienie!H:H,ROW()*2+1))), AND(NOT(ISBLANK(INDEX(Zestawienie!I:I,ROW()*2+1))), ISBLANK(INDEX(Zestawienie!J:J,ROW()*2+1))), AND(NOT(ISBLANK(INDEX(Zestawienie!K:K,ROW()*2+1))), ISBLANK(INDEX(Zestawienie!L:L,ROW()*2+1))) ), "Zajęte", "Wolne" ) )} -> Wolne | D16: {=IFERROR( IF( ISBLANK(INDEX(Zestawienie!B:B, MATCH(A16, Zestawienie!A:A, 0))), "", IF(C16="Wolne", IF( OR( ISBLANK(INDEX(Zestawienie!B:B, MATCH(A16, Zestawienie!A:A, 0))), NOT(ISNUMBER(INDEX(Zestawienie!B:B, MATCH(A16, Zestawienie!A:A, 0)))) ), "", TODAY()-INDEX(Zestawienie!B:B, MATCH(A16, Zestawienie!A:A, 0)) ), IF(OR(C16="Zajęte", C16="Spóźnione"), IF( ISBLANK( MAX( IF(ISNUMBER(INDEX(Zestawienie!C:C, 2*ROW()+1)), INDEX(Zestawienie!C:C, 2*ROW()+1), 0), IF(ISNUMBER(INDEX(Zestawienie!E:E, 2*ROW()+1)), INDEX(Zestawienie!E:E, 2*ROW()+1), 0), IF(ISNUMBER(INDEX(Zestawienie!G:G, 2*ROW()+1)), INDEX(Zestawienie!G:G, 2*ROW()+1), 0), IF(ISNUMBER(INDEX(Zestawienie!I:I, 2*ROW()+1)), INDEX(Zestawienie!I:I, 2*ROW()+1), 0), IF(ISNUMBER(INDEX(Zestawienie!K:K, 2*ROW()+1)), INDEX(Zestawienie!K:K, 2*ROW()+1), 0) ) ), "", IF(C16="Zajęte", TODAY()-MAX( IF(ISNUMBER(INDEX(Zestawienie!C:C, 2*ROW()+1)), INDEX(Zestawienie!C:C, 2*ROW()+1), 0), IF(ISNUMBER(INDEX(Zestawienie!E:E, 2*ROW()+1)), INDEX(Zestawienie!E:E, 2*ROW()+1), 0), IF(ISNUMBER(INDEX(Zestawienie!G:G, 2*ROW()+1)), INDEX(Zestawienie!G:G, 2*ROW()+1), 0), IF(ISNUMBER(INDEX(Zestawienie!I:I, 2*ROW()+1)), INDEX(Zestawienie!I:I, 2*ROW()+1), 0), IF(ISNUMBER(INDEX(Zestawienie!K:K, 2*ROW()+1)), INDEX(Zestawienie!K:K, 2*ROW()+1), 0) ), MAX(0, TODAY()-MAX( IF(ISNUMBER(INDEX(Zestawienie!C:C, 2*ROW()+1)), INDEX(Zestawienie!C:C, 2*ROW()+1), 0), IF(ISNUMBER(INDEX(Zestawienie!E:E, 2*ROW()+1)), INDEX(Zestawienie!E:E, 2*ROW()+1), 0), IF(ISNUMBER(INDEX(Zestawienie!G:G, 2*ROW()+1)), INDEX(Zestawienie!G:G, 2*ROW()+1), 0), IF(ISNUMBER(INDEX(Zestawienie!I:I, 2*ROW()+1)), INDEX(Zestawienie!I:I, 2*ROW()+1), 0), IF(ISNUMBER(INDEX(Zestawienie!K:K, 2*ROW()+1)), INDEX(Zestawienie!K:K, 2*ROW()+1), 0) )-120) ) ), "" ) ) ), "")} -> 208
